Workbook

Sheet DATA_INFO
A1: Start Data | B1: End Data
A2: 9 | B2: 16

Sheet Datatable
A1: NO | B1: ACTION | C1: SCRIPT_ALIAS | D1: DATA | E1: SCENARIO | F1: USER ID READER | G1: PASSWORD READER | H1: USER ID EDITOR | I1: PASSWORD EDITOR | J1: USER ID SUPER EDITOR A | K1: PASSWORD SUPER EDITOR A | L1: USER ID SUPER EDITOR B | M1: PASSWORD SUPER EDITOR B | N1: USER ID PUBLISHER A | O1: PASSWORD PUBLISHER A | P1: USER ID PUBLISHER B | Q1: PASSWORD PUBLISHER B | R1: URL PAKAR | S1: TEST_GROUP | T1: STATUS | U1: KETERANGAN
A2: 1 | B2: Tambah Approve Super Editor | D2: Data A | E2: Tambah Approved Artikel ke Super Editor | F2: u068251 | G2: password | H2: u060242 | I2: password | J2: u063597 | K2: password | L2: u064475 | M2: password | N2: u067020 | O2: password | P2: u541785 | Q2: password | R2: https://pakar-fe.jdlapp.apps.ocpdevgra.dti.co.id/homepage | S2: AUTOMATIONTEST
A3: 2 | B3: Tambah Reject Super Editor | D3: Data B | E3: Tambah Reject Artikel ke Super Editor | F3: u068251 | G3: password | H3: u060242 | I3: password | J3: u063597 | K3: password | L3: u064475 | M3: password | N3: u067020 | O3: password | P3: u541785 | Q3: password | R3: https://pakar-fe.jdlapp.apps.ocpdevgra.dti.co.id/homepage | S3: AUTOMATIONTEST
A4: 3 | B4: Tambah Approve Super Editor | D4: Data C | E4: Tambah Approved VP ke Super Editor | F4: u068251 | G4: password | H4: u060242 | I4: password | J4: u063597 | K4: password | L4: u064475 | M4: password | N4: u067020 | O4: password | P4: u541785 | Q4: password | R4: https://pakar-fe.jdlapp.apps.ocpdevgra.dti.co.id/homepage | S4: AUTOMATIONTEST
A5: 4 | B5: Tambah Reject Super Editor | D5: Data D | E5: Tambah Reject VP ke Super Editor | F5: u068251 | G5: password | H5: u060242 | I5: password | J5: u063597 | K5: password | L5: u064475 | M5: password | N5: u067020 | O5: password | P5: u541785 | Q5: password | R5: https://pakar-fe.jdlapp.apps.ocpdevgra.dti.co.id/homepage | S5: AUTOMATIONTEST
A6: 5 | B6: Tambah Ubah Approve SuperEditor | D6: Data E | E6: Tambah Ubah Approve Artikel ke Super Editor | F6: u068251 | G6: password | H6: u060242 | I6: password | J6: u063597 | K6: password | L6: u064475 | M6: password | N6: u067020 | O6: password | P6: u541785 | Q6: password | R6: https://pakar-fe.jdlapp.apps.ocpdevgra.dti.co.id/homepage | S6: AUTOMATIONTEST
A7: 6 | B7: Tambah Ubah Reject Super Editor | D7: Data F | E7: Tambah Ubah Reject Artikel ke Super Editor | F7: u068251 | G7: password | H7: u060242 | I7: password | J7: u063597 | K7: password | L7: u064475 | M7: password | N7: u067020 | O7: password | P7: u541785 | Q7: password | R7: https://pakar-fe.jdlapp.apps.ocpdevgra.dti.co.id/homepage | S7: AUTOMATIONTEST
A8: 7 | B8: Tambah Ubah Approve Notif SE | D8: Data G | E8: Tambah Ubah Approve VP ke Super Editor | F8: u068251 | G8: password | H8: u060242 | I8: password | J8: u063597 | K8: password | L8: u064475 | M8: password | N8: u067020 | O8: password | P8: u541785 | Q8: password | R8: https://pakar-fe.jdlapp.apps.ocpdevgra.dti.co.id/homepage | S8: AUTOMATIONTEST
A9: 8 | B9: Tambah Ubah Reject Notif SE | D9: Data H | E9: Tambah Ubah Reject VP ke Super Editor | F9: u068251 | G9: password | H9: u060242 | I9: password | J9: u063597 | K9: password | L9: u064475 | M9: password | N9: u067020 | O9: password | P9: u541785 | Q9: password | R9: https://pakar-fe.jdlapp.apps.ocpdevgra.dti.co.id/homepage | S9: AUTOMATIONTEST
A10: 9 | B10: Tambah Approve Publisher | D10: Data I | E10: Tambah Approved Artikel ke Publisher | F10: u068251 | G10: password | H10: u060242 | I10: password | J10: u068843 | K10: password | L10: u064475 | M10: password | N10: u067020 | O10: password | P10: u541785 | Q10: password | R10: https://pakar-fe.jdlapp.apps.ocpdevgra.dti.co.id/homepage | S10: AUTOMATIONTEST
A11: 10 | B11: Tambah Reject Publisher | D11: Data J | E11: Tambah Reject Artikel ke Publisher | F11: u068251 | G11: password | H11: u060242 | I11: password | J11: u068843 | K11: password | L11: u064475 | M11: password | N11: u067020 | O11: password | P11: u541785 | Q11: password | R11: https://pakar-fe.jdlapp.apps.ocpdevgra.dti.co.id/homepage | S11: AUTOMATIONTEST
A12: 11 | B12: Tambah Approve Publisher | D12: Data K | E12: Tambah Approved VP ke Publisher | F12: u068251 | G12: password | H12: u060242 | I12: password | J12: u068843 | K12: password | L12: u064475 | M12: password | N12: u067020 | O12: password | P12: u541785 | Q12: password | R12: https://pakar-fe.jdlapp.apps.ocpdevgra.dti.co.id/homepage | S12: AUTOMATIONTEST
A13: 12 | B13: Tambah Reject Publisher | D13: Data L | E13: Tambah Reject VP ke Publisher | F13: u068251 | G13: password | H13: u060242 | I13: password | J13: u068843 | K13: password | L13: u064475 | M13: password | N13: u067020 | O13: password | P13: u541785 | Q13: password | R13: https://pakar-fe.jdlapp.apps.ocpdevgra.dti.co.id/homepage | S13: AUTOMATIONTEST
... A39: 38 | B39: Akses SKSE Bookmark Reader | D39: Data E | E39: Akses Bookmark Halaman Artikel dan SKSE Reader | F39: u068251 | G39: password | H39: u060242 | I39: password | J39: u063597 | K39: password | L39: u064475 | M39: password | N39: u067020 | O39: password | P39: u541785 | Q39: password | R39: https://pakar-fe.jdlapp.apps.ocpdevgra.dti.co.id/homepage | S39: AUTOMATIONTEST
A40: 39 | B40: Create Balas Feedback Super Edi | E40: Create Balas Feedback Super Editor | F40: u068251 | G40: password | H40: u060242 | I40: password | J40: u063597 | K40: password | L40: u064475 | M40: password | N40: u067020 | O40: password | P40: u541785 | Q40: password | R40: https://pakar-fe.jdlapp.apps.ocpdevgra.dti.co.id/homepage | S40: AUTOMATIONTEST
A41: 40 | B41: Create Balas Feedback Publisher | E41: Create Balas Feedback Publisher | F41: u068251 | G41: password | H41: u060242 | I41: password | J41: u063597 | K41: password | L41: u064475 | M41: password | N41: u067020 | O41: password | P41: u541785 | Q41: password | R41: https://pakar-fe.jdlapp.apps.ocpdevgra.dti.co.id/homepage | S41: AUTOMATIONTEST
A42: 41 | B42: Create Balas Feedback Reader | E42: Create Balas Feedback Reader | F42: u068251 | G42: password | H42: u060242 | I42: password | J42: u063597 | K42: password | L42: u064475 | M42: password | N42: u067020 | O42: password | P42: u541785 | Q42: password | R42: https://pakar-fe.jdlapp.apps.ocpdevgra.dti.co.id/homepage | S42: AUTOMATIONTEST
A43: 42 | B43: Balas dan Export Feedback | E43: Akses Balas dan Export Data Feedback | F43: u068251 | G43: password | H43: u060242 | I43: password | J43: u063597 | K43: password | L43: u064475 | M43: password | N43: u067020 | O43: password | P43: u541785 | Q43: password | R43: https://pakar-fe.jdlapp.apps.ocpdevgra.dti.co.id/homepage | S43: AUTOMATIONTEST
A44: 43 | B44: Akses Feedback Sudah Baik | E44: Akses Video Artikel dan Feedback Sudah Baik | F44: u068251 | G44: password | H44: u060242 | I44: password | J44: u063597 | K44: password | L44: u064475 | M44: password | N44: u067020 | O44: password | P44: u541785 | Q44: password | R44: https://pakar-fe.jdlapp.apps.ocpdevgra.dti.co.id/homepage | S44: AUTOMATIONTEST
A45: 44 | B45: Akses Assign PIC Feedback | E45: Akses Assign PIC Feedback | F45: u068251 | G45: password | H45: u060242 | I45: password | J45: u063597 | K45: password | L45: u064475 | M45: password | N45: u067020 | O45: password | P45: u541785 | Q45: password | R45: https://pakar-fe.jdlapp.apps.ocpdevgra.dti.co.id/homepage | S45: AUTOMATIONTEST
A46: 45 | B46: Akses Abjad Ajukan Glossary SE | E46: Akses Glossary Abjad dan Ajukan Glossary Super Editor | F46: u068251 | G46: password | H46: u060242 | I46: password | J46: u068843 | K46: password | L46: u064475 | M46: password | N46: u067020 | O46: password | P46: u541785 | Q46: password | R46: https://pakar-fe.jdlapp.apps.ocpdevgra.dti.co.id/homepage | S46: AUTOMATIONTEST
A47: 46 | B47: Akses Abjad Ajukan Glossary R | E47: Akses Glossary Abjad dan Ajukan Glossary Reader | F47: u068251 | G47: password | H47: u060242 | I47: password | J47: u063597 | K47: password | L47: u064475 | M47: password | N47: u067020 | O47: password | P47: u541785 | Q47: password | R47: https://pakar-fe.jdlapp.apps.ocpdevgra.dti.co.id/homepage | S47: AUTOMATIONTEST
A48: 47 | B48: Akses Abjad Ajukan Glossary E | E48: Akses Glossary Abjad dan Ajukan Glossary Editor | F48: u068251 | G48: password | H48: u060242 | I48: password | J48: u063597 | K48: password | L48: u064475 | M48: password | N48: u067020 | O48: password | P48: u541785 | Q48: password | R48: https://pakar-fe.jdlapp.apps.ocpdevgra.dti.co.id/homepage | S48: AUTOMATIONTEST
A49: 48 | B49: Akses Abjad Ajukan Glossary P | E49: Akses Glossary Abjad dan Ajukan Glossary Publisher | F49: u068251 | G49: password | H49: u060242 | I49: password | J49: u063597 | K49: password | L49: u064475 | M49: password | N49: u067020 | O49: password | P49: u541785 | Q49: password | R49: https://pakar-fe.jdlapp.apps.ocpdevgra.dti.co.id/homepage | S49: AUTOMATIONTEST
A50: 49 | B50: Export to XLS-Data yang Tampil | E50: Export to XLS - Data yang Tampil | F50: u068251 | G50: password | H50: u060242 | I50: password | J50: u068843 | K50: password | L50: u064475 | M50: password | N50: u067020 | O50: password | P50: u541785 | Q50: password | R50: https://pakar-fe.jdlapp.apps.ocpdevgra.dti.co.id/homepage | S50: AUTOMATIONTEST
A51: 50 | B51: Export File Artikel | D51: Data M | E51: Export File Artikel | F51: u068251 | G51: password | H51: u060242 | I51: password | J51: u068843 | K51: password | L51: u064475 | M51: password | N51: u067020 | O51: password | P51: u541785 | Q51: password | R51: https://pakar-fe.jdlapp.apps.ocpdevgra.dti.co.id/homepage | S51: AUTOMATIONTEST
A52: 51 | B52: Akses Pengecekan Tombol | D52: Data M | E52: Akses Artikel Pengecekan Tombol | F52: u068251 | G52: password | H52: u060242 | I52: password | J52: u068843 | K52: password | L52: u064475 | M52: password | N52: u067020 | O52: password | P52: u541785 | Q52: password | R52: https://pakar-fe.jdlapp.apps.ocpdevgra.dti.co.id/homepage | S52: AUTOMATIONTEST
A53: 52 | B53: Simpan dan Kirim Riwayat Versi | D53: Data A | E53: Akses Riwayat Versi Simpan dan Kirim | F53: u068251 | G53: password | H53: u060242 | I53: password | J53: u063597 | K53: password | L53: u064475 | M53: password | N53: u067020 | O53: password | P53: u541785 | Q53: password | R53: https://pakar-fe.jdlapp.apps.ocpdevgra.dti.co.id/homepage | S53: AUTOMATIONTEST
A54: 53 | B54: Riwayat Versi Approved Super Ed | D54: Data E | E54: Akses Riwayat Versi Approved Super Editor | F54: u068251 | G54: password | H54: u060242 | I54: password | J54: u063597 | K54: password | L54: u064475 | M54: password | N54: u067020 | O54: password | P54: u541785 | Q54: password | R54: https://pakar-fe.jdlapp.apps.ocpdevgra.dti.co.id/homepage | S54: AUTOMATIONTEST
A55: 54 | B55: Riwayat Versi Approved Publishe | D55: Data M | E55: Akses Riwayat Versi Approved Publisher | F55: u068251 | G55: password | H55: u060242 | I55: password | J55: u068843 | K55: password | L55: u064475 | M55: password | N55: u067020 | O55: password | P55: u541785 | Q55: password | R55: https://pakar-fe.jdlapp.apps.ocpdevgra.dti.co.id/homepage | S55: AUTOMATIONTEST
A56: 55 | B56: Riwayat Versi Editor Approved P | D56: Data I | E56: Akses Riwayat Versi Editor Approved Publisher | F56: u068251 | G56: password | H56: u060242 | I56: password | J56: u063597 | K56: password | L56: u064475 | M56: password | N56: u067020 | O56: password | P56: u541785 | Q56: password | R56: https://pakar-fe.jdlapp.apps.ocpdevgra.dti.co.id/homepage | S56: AUTOMATIONTEST
A57: 56 | B57: Tambah Kategori Menu | E57: Tambah Kategori Menu | F57: u068251 | G57: password | H57: u060242 | I57: password | J57: u063597 | K57: password | L57: u064475 | M57: password | N57: u067020 | O57: password | P57: u541785 | Q57: password | R57: https://pakar-fe.jdlapp.apps.ocpdevgra.dti.co.id/homepage | S57: AUTOMATIONTEST
A58: 57 | B58: Ubah Kategori Menu | E58: Ubah Kategori Menu | F58: u068251 | G58: password | H58: u060242 | I58: password | J58: u063597 | K58: password | L58: u064475 | M58: password | N58: u067020 | O58: password | P58: u541785 | Q58: password | R58: https://pakar-fe.jdlapp.apps.ocpdevgra.dti.co.id/homepage | S58: AUTOMATIONTEST
A59: 58 | B59: Hapus Kategori Menu | E59: Hapus Kategori Menu | F59: u068251 | G59: password | H59: u060242 | I59: password | J59: u063597 | K59: password | L59: u064475 | M59: password | N59: u067020 | O59: password | P59: u541785 | Q59: password | R59: https://pakar-fe.jdlapp.apps.ocpdevgra.dti.co.id/homepage | S59: AUTOMATIONTEST
A60: 59 | B60: Assign Divisi | E60: Assign Divisi | F60: u068251 | G60: password | H60: u060242 | I60: password | J60: u063597 | K60: password | L60: u064475 | M60: password | N60: u067020 | O60: password | P60: u541785 | Q60: password | R60: https://pakar-fe.jdlapp.apps.ocpdevgra.dti.co.id/homepage | S60: AUTOMATIONTEST
A61: 60 | B61: Hapus Approved | E61: Hapus Approved | F61: u068251 | G61: password | H61: u060242 | I61: password | J61: u068843 | K61: password | L61: u064475 | M61: password | N61: u067020 | O61: password | P61: u541785 | Q61: password | R61: https://pakar-fe.jdlapp.apps.ocpdevgra.dti.co.id/homepage | S61: AUTOMATIONTEST
A62: 61 | B62: Hapus Reject | E62: Hapus Reject | F62: u068251 | G62: password | H62: u060242 | I62: password | J62: u068843 | K62: password | L62: u064475 | M62: password | N62: u067020 | O62: password | P62: u541785 | Q62: password | R62: https://pakar-fe.jdlapp.apps.ocpdevgra.dti.co.id/homepage | S62: AUTOMATIONTEST
A63: 62 | B63: Tambah Ubah Approved P Pop Up | D63: Data Q | E63: Tambah Ubah Approved VP Publisher Pop Up | F63: u068251 | G63: password | H63: u060242 | I63: password | J63: u068843 | K63: password | L63: u064475 | M63: password | N63: u067020 | O63: password | P63: u541785 | Q63: password | R63: https://pakar-fe.jdlapp.apps.ocpdevgra.dti.co.id/homepage | S63: AUTOMATIONTEST
A64: 63 | B64: Tambah Ubah Reject P Pop Up | D64: Data R | E64: Tambah Ubah Reject VP Publisher Pop Up | F64: u068251 | G64: password | H64: u060242 | I64: password | J64: u068843 | K64: password | L64: u064475 | M64: password | N64: u067020 | O64: password | P64: u541785 | Q64: password | R64: https://pakar-fe.jdlapp.apps.ocpdevgra.dti.co.id/homepage | S64: AUTOMATIONTEST
A65: 64 | B65: Tambah Ubah Approved P Pop Up | D65: Data S | E65: Tambah Ubah Approved Artikel Publisher Pop Up | F65: u068251 | G65: password | H65: u060242 | I65: password | J65: u068843 | K65: password | L65: u064475 | M65: password | N65: u067020 | O65: password | P65: u541785 | Q65: password | R65: https://pakar-fe.jdlapp.apps.ocpdevgra.dti.co.id/homepage | S65: AUTOMATIONTEST
...

Sheet Otomasi Pakar
A1: Testcase | B1: Is_Running | C1: Keyword | D1: Pagename | E1: ObjectName | F1: ObjectType | G1: Value | H1: Application
A2: ALL FITURE | B2: Yes | H2: PAKAR
C3: save_action | E3: [SAVE_ACTION_1] | G3: Login
C4: save_action | E4: [SAVE_ACTION_2] | G4: =Datatable!#REF! -> #REF!
C5: save_action | E5: [SAVE_ACTION_3] | G5: =Datatable!#REF! -> #REF!
C6: save_action | E6: [SAVE_ACTION_4] | G6: =Datatable!#REF! -> #REF!
C7: save_action | E7: [SAVE_ACTION_5] | G7: =Datatable!#REF! -> #REF!
C8: save_action | E8: [SAVE_ACTION_6] | G8: =Datatable!#REF! -> #REF!
C9: save_action | E9: [SAVE_ACTION_7] | G9: =Datatable!#REF! -> #REF!
C10: save_action | E10: [SAVE_ACTION_8] | G10: Logout
C11: read_script | G11: [SAVE_ACTION_#]

Sheet Data Script
A1: NO | B1: FEATURE
A2: 1 | B2: Login Editor
A3: 1 | B3: Tambah Artikel
A4: 1 | B4: Deskripsi Singkat
A5: 1 | B5: Tambah Gambar
A6: 1 | B6: Video Artikel
A7: 1 | B7: Tambah Ubah Topik
A8: 1 | B8: SK SE Referensi
A9: 1 | B9: Informasi Terkait
A10: 1 | B10: Simpan
A11: 1 | B11: Logout
A12: 2 | B12: Login Editor
A13: 2 | B13: Akses Artikel My Pages Draft
... A52: 7 | B52: Logout

Sheet Source
A1: Login Reader | B1: AutoSave | C1: Akses Artikel My Pages | D1: Akses Edit Halaman Artikel VP | E1: Tambah Artikel VP | F1: Copy Link Bookmark | H1: Akses Search Glossary | I1: Page Notifikasi - Closed | K1: Reader: | L1: Super Editor: | M1: Editor: | N1: Publisher: | O1: Pass Supereditor: | P1: Pass Publisher | S1: Tambah Artikel
A2: Login Editor | B2: Simpan | C2: Akses Artikel Contens | D2: Akses Edit Pop Up Notifikasi | E2: Edit Artikel VP | F2: Copy Link Bookmark Checkbox | H2: Akses Glossary Abjad | I2: Pop Up Notifikasi - Closed | K2: u076929 | L2: u066099 | M2: u060242 | N2: u541785 | O2: password | P2: password | S2: Tambah Judul
A3: Login Super Editor | B3: Simpan dan Kirim | C3: Akses Edit Page Notifikasi | D3: Batal Kirim Artikel | E3: Hapus Bookmark | H3: Ajukan Glossary | I3: Page Notifikasi - Waiting for User | K3: u064959 | L3: u053296 | M3: u059613 | N3: u067020 | O3: feb022025 | P3: 21029842 | S3: Deskripsi Singkat
A4: Login Publisher | B4: Batal Simpan | C4: Akses Edit My Pages Draft | D4: Batal Ubah Versi Artikel | E4: Hapus Bookmark Checkbox | H4: Akses Tab Glossary Main Search | I4: Pop Up Notifikasi - Waiting for User | K4: u068251 | L4: u065951 | M4: U555742 | N4: U541785 | O4: lovemonth25 | P4: Farina2003 | S4: Tambah Gambar
B5: Batal Simpan dan Kirim | C5: Akses Artikel Judul Feedback | D5: Akses Edit My Pages | E5: Pengecekan Tombol | L5: u068843 | N5: U543390 | S5: Video Artikel
B6: Preview | C6: Akses Artikel Isi Feedback | D6: Akses Edit Contens Artikel | E6: Reject My Pages | L6: u063597 | S6: Tambah Ubah Topik
B7: Kembali ke Halaman Editor | C7: Akses Artikel Page Notifikasi | D7: Akses Edit Contens Virtual Page | E7: Reject Page Notifikasi | L7: u064475 | S7: SK SE Referensi
B8: Riwayat Versi | C8: Akses Artikel Hyperlink Isi Art | D8: Akses Video Artikel | E8: Approve My Pages | S8: Informasi Terkait
B9: Keluar | C9: Akses Artikel Main Search | D9: Akses SKSE | E9: Approve Page Notifikasi | S9: Suggestion
B10: Batal Keluar | C10: Akses Artikel Burger Menu | E10: Sisipkan VP
C11: Akses Artikel Terbaru | E11: Akses Riwayat Versi
C12: Akses Artikel Rekomendasi | E12: Akses Riwayat Versi Reader
C13: Akses Artikel Page FAQ | E13: Unsisip VP
C14: Akses Artikel Isi FAQ | E14: Hapus Deskripsi
C15: Akses Artikel Bookmark PAKAR | E15: Hapus Artikel My Pages Draft
C16: Akses Artikel Link Glossary | E16: Hapus Artikel My Pages Approve
C17: Akses Artikel Informasi Terkait | E17: Hapus Artikel Contents Semua
C18: Akses Artikel Digunakan Oleh | E18: Hapus Artikel Contents Artikel
C19: Akses Video Artikel | E19: Hapus Artikel Contents VP
C20: Akses SKSE | E20: Tambah Hapus Bookmark Artikel
E21: Tambah Hapus Bookmark Akordion
E22: Copy Link Bookmark
E23: Hapus Single Bookmark
E24: Hapus Multiple Bookmark
E25: Akses Search Glossary
E26: Akses Glossary Abjad
E27: Akses Tab Glossary Main Search
E28: Ajukan Glossary
E29: Create Feedback
E30: Check Feedback Populer
E31: Feedback Sudah Baik
E32: Akses Dashboard Feedback
... E51: Checklist Kategori

Sheet Data Akses Artikel
A1: NO | B1: KATEGORI | C1: SUBKATEGORI | D1: MY PAGES (draft/pending/approved/rejected) | E1: CONTENTS (Semua/Artikel/Virtual Page) | F1: JUDUL_FAQ | G1: JUDUL_GLOSSARY | H1: INFORMASI_TERKAIT | I1: DIGUNAKAN_OLEH | J1: HYPERLINK | K1: NAMA Artikel 04062025 (Didalam Folder pisahkan ;) | L1: TANGGAL | M1: USERNAME SKSE | N1: PASSWORD SKSE | O1: SK/SE
A2: 5 | D2: draft | K2: Tambah Ubah Approved Super Editor Artikel 04062025 E | M2: u064959 | N2: erickoo087
A3: 6 | D3: draft | K3: Tambah Ubah Reject Super Editor Artikel 04062025 F | M3: u064959 | N3: erickoo087
A4: 7 | D4: draft | K4: Tambah Ubah Approved Super Editor VP 04062025 G | M4: u064959 | N4: erickoo087
A5: 8 | D5: draft | K5: Tambah Ubah Reject Super Editor VP 04062025 H | M5: u064959 | N5: erickoo087
A6: 13 | D6: draft | K6: Tambah Ubah Approved Publisher Artikel 04062025 M | M6: u064959 | N6: erickoo087
A7: 14 | D7: draft | K7: Tambah Ubah Reject Publisher Artikel 04062025 N | M7: u064959 | N7: erickoo087
A8: 15 | D8: draft | K8: Tambah Ubah Approved Publisher VP 04062025 O | M8: u064959 | N8: erickoo087
A9: 16 | D9: draft | K9: Tambah Ubah Reject Publisher VP 04062025 P | M9: u064959 | N9: erickoo087
A10: 17 | K10: Tambah Approved Super Editor Artikel 04062025 A | M10: u064959 | N10: erickoo087
A11: 18 | K11: Ubah Tambah Approved Super Editor Artikel 04062025 A | M11: u064959 | N11: erickoo087
A12: 19 | K12: Tambah Approved Super Editor VP 04062025 C | M12: u064959 | N12: erickoo087
A13: 20 | K13: Ubah Tambah Approved Super Editor VP 04062025 C | M13: u064959 | N13: erickoo087
A14: 21 | K14: Ubah Tambah Ubah Approved Super Editor Artikel 04062025 E | M14: u064959 | N14: erickoo087
A15: 22 | K15: Ubah Lagii Tambah Ubah Approved Super Editor Artikel 04062025 E | M15: u064959 | N15: erickoo087
A16: 23 | K16: Ubah Tambah Ubah Approved Super Editor VP 04062025 G | M16: u064959 | N16: erickoo087
A17: 24 | K17: Ubah Lagii Tambah Ubah Approved Super Editor VP 04062025 G | M17: u064959 | N17: erickoo087
A18: 25 | K18: Tambah Approved Publisher Artikel 04062025 I | M18: u064959 | N18: erickoo087
A19: 26 | K19: Ubah Tambah Approved Publisher Artikel 04062025 I | M19: u064959 | N19: erickoo087
A20: 27 | K20: Tambah Approved Publisher VP 04062025 K | M20: u064959 | N20: erickoo087
A21: 28 | K21: Ubah Tambah Approved Publisher VP 04062025 K | M21: u064959 | N21: erickoo087
... A26: 33 | K26: Ubah Tambah Approved Super Editor Artikel 04062025 A | M26: u064959 | N26: erickoo087
A27: 34 | B27: Produk Untuk Nasabah | C27: Produk Dana | K27: Ubah Tambah Approved Publisher Artikel 04062025 I | M27: u064959 | N27: erickoo087
A28: 35 | J28: Weekend Banking | K28: Ubah Tambah Approved Super Editor Artikel 04062025 A | M28: u064959 | N28: erickoo087 | O28: 504/SE/POL/2022
A29: 36 | K29: Ubah Lagii Tambah Ubah Approved Super Editor Artikel 04062025 E | M29: u064959 | N29: erickoo087
A30: 37 | B30: Produk Untuk Nasabah | C30: Produk Dana | K30: Ubah Tambah Approved Publisher Artikel 04062025 I | M30: u064959 | N30: erickoo087
A31: 38 | J31: Weekend Banking | K31: Ubah Tambah Ubah Approved Super Editor Artikel 04062025 E | M31: u064959 | N31: erickoo087 | O31: 504/SE/POL/2022
A32: 39 | H32: Weekend Banking | K32: BCA Prioritas
A33: 40 | H33: Weekend Banking | K33: BCA Prioritas
A34: 41 | H34: Weekend Banking | K34: BCA Prioritas
A35: 43 | H35: Weekend Banking | K35: BCA Prioritas
A36: 45 | G36: Aplikasi MyBCA
A37: 46 | G37: Pandu dan Sekar
A38: 47 | G38: Aplikasi MyBCA
A39: 48 | G39: Pandu dan Sekar
A40: 50 | B40: Produk Untuk Nasabah | C40: Produk Dana | K40: Ubah Lagii Tambah Ubah Approved Publisher Artikel 04062025 M
A41: 51 | B41: Produk Untuk Nasabah | C41: Produk Dana | K41: Ubah Lagii Tambah Ubah Approved Publisher Artikel 04062025 M
A42: 52 | B42: Produk Untuk Nasabah | C42: Produk Dana | K42: Ubah Lagii Tambah Approved Super Editor Artikel 04062025 A
A43: 53 | B43: Produk Untuk Nasabah | C43: Produk Dana | K43: Ubah Tambah Ubah Approved Super Editor Artikel 04062025 E
A44: 54 | B44: Produk Untuk Nasabah | C44: Produk Dana | K44: Ubah Tambah Ubah Approved Publisher Artikel 04062025 M
...

Sheet Data Akses Edit Artikel
A1: NO | B1: NAMA Artikel 04062025 (Didalam Folder pisahkan ;) | C1: MY PAGES (draft/pending/approved) | D1: PILIH | E1: TANGGAL
A2: 17 | B2: Ubah Tambah Approved Super Editor Artikel 04062025 A | C2: draft
A3: 18 | B3: Ubah Lagii Tambah Approved Super Editor Artikel 04062025 A | C3: draft
A4: 19 | B4: Ubah Tambah Approved Super Editor VP 04062025 C | C4: draft
A5: 20 | B5: Ubah Lagii Tambah Approved Super Editor VP 04062025 C | C5: draft
A6: 21 | B6: Ubah Lagii Tambah Ubah Approved Super Editor Artikel 04062025 E | C6: draft
A7: 22 | B7: Ubah Tambah Ubah Approved Super Editor Artikel 04062025 E | C7: draft
A8: 23 | B8: Ubah Lagii Tambah Ubah Approved Super Editor VP 04062025 G | C8: draft
A9: 24 | B9: Ubah Tambah Ubah Approved Super Editor VP 04062025 G | C9: draft
A10: 25 | B10: Ubah Tambah Approved Publisher Artikel 04062025 I | C10: draft
A11: 26 | B11: Ubah Lagii Tambah Approved Publisher Artikel 04062025 I | C11: draft
A12: 27 | B12: Ubah Tambah Approved Publisher VP 04062025 K | C12: draft
A13: 28 | B13: Ubah Lagii Tambah Approved Publisher VP 04062025 K | C13: draft
... A31: 76 | B31: Ubah Lagii Tambah Ubah Approved Publisher Artikel 04062025 M | C31: draft

Sheet Data Tambah Artikel VP
A1: NO | B1: PILIH (Artikel/Virtual Page) | C1: NAMA Artikel 04062025 VP 04062025 | D1: BENTUK VIRTUAL PAGE | E1: LOKASI ARTIKEL VP | F1: REKOMENDASI TEMPLATE
A2: 1 | B2: Artikel | C2: Tambah Approved Super Editor Artikel 04062025 A | E2: Produk Untuk Nasabah;Produk Dana | F2: Basic
A3: 2 | B3: Artikel | C3: Tambah Reject Super Editor Artikel 04062025 B | E3: Produk Untuk Nasabah;Produk Dana | F3: Basic
A4: 3 | B4: Virtual Page | C4: Tambah Approved Super Editor VP 04062025 C | D4: Atribut Page | E4: Virtual Page;Atribut;Atribut Produk Digital | F4: Basic
A5: 4 | B5: Virtual Page | C5: Tambah Reject Super Editor VP 04062025 D | D5: Micro Information | E5: Virtual Page;Atribut;Atribut Produk Digital
A6: 5 | B6: Artikel | C6: Tambah Ubah Approved Super Editor Artikel 04062025 E | E6: Produk Untuk Nasabah;Produk Dana | F6: Basic
A7: 6 | B7: Artikel | C7: Tambah Ubah Reject Super Editor Artikel 04062025 F | E7: Produk Untuk Nasabah;Produk Dana | F7: Basic
A8: 7 | B8: Virtual Page | C8: Tambah Ubah Approved Super Editor VP 04062025 G | D8: Atribut Page | E8: Virtual Page;Atribut;Atribut Produk Digital | F8: Basic
A9: 8 | B9: Virtual Page | C9: Tambah Ubah Reject Super Editor VP 04062025 H | D9: Micro Information | E9: Virtual Page;Atribut;Atribut Produk Digital
A10: 9 | B10: Artikel | C10: Tambah Approved Publisher Artikel 04062025 I | E10: Produk Untuk Nasabah;Produk Dana | F10: Basic
A11: 10 | B11: Artikel | C11: Tambah Reject Publisher Artikel 04062025 J | E11: Produk Untuk Nasabah;Produk Dana | F11: Basic
A12: 11 | B12: Virtual Page | C12: Tambah Approved Publisher VP 04062025 K | D12: Atribut Page | E12: Virtual Page;Atribut;Atribut Produk Digital | F12: Basic
A13: 12 | B13: Virtual Page | C13: Tambah Reject Publisher VP 04062025 L | D13: Micro Information | E13: Virtual Page;Atribut;Atribut Produk Digital
A14: 13 | B14: Artikel | C14: Tambah Ubah Approved Publisher Artikel 04062025 M | E14: Produk Untuk Nasabah;Produk Dana | F14: Basic
A15: 14 | B15: Artikel | C15: Tambah Ubah Reject Publisher Artikel 04062025 N | E15: Produk Untuk Nasabah;Produk Dana | F15: Basic
A16: 15 | B16: Virtual Page | C16: Tambah Ubah Approved Publisher VP 04062025 O | D16: Atribut Page | E16: Virtual Page;Atribut;Atribut Produk Digital | F16: Basic
A17: 16 | B17: Virtual Page | C17: Tambah Ubah Reject Publisher VP 04062025 P | D17: Micro Information | E17: Virtual Page;Atribut;Atribut Produk Digital
A18: 62 | B18: Virtual Page | C18: Tambah Ubah Approved VP 04062025 Q Publisher Pop Up | D18: Atribut Page | E18: Virtual Page;Atribut;Atribut Produk Digital | F18: Basic
A19: 63 | B19: Virtual Page | C19: Tambah Ubah Reject VP 04062025 R Publisher Pop Up | D19: Micro Information | E19: Virtual Page;Atribut;Atribut Produk Digital
A20: 64 | B20: Artikel | C20: Tambah Ubah Approved Artikel 04062025 S Publisher Pop Up | E20: Produk Untuk Nasabah;Produk Dana | F20: Basic
A21: 65 | B21: Artikel | C21: Tambah Ubah Reject Artikel 04062025 T Publisher Pop Up | E21: Produk Untuk Nasabah;Produk Dana | F21: Basic

Sheet Data Tambah Isi Artikel VP
A1: NO | B1: DESKRIPSI SINGKAT | C1: PATH FILE GAMBAR | D1: URL VIDEO | E1: SK/SE REFERENSI | F1: INFORMASI TERKAIT | G1: SUGGESTION | H1: SIMPAN DAN KIRIM | I1: CATATAN SIMPAN & KIRIM | J1: Preview (Ya/Tidak) | K1: Riwayat Versi (Ya/Tidak) | L1: Pilih (AutoSave/Simpan/Simpan dan Kirim/Batal Simpan/Batal Simpan dan Kirim) | M1: Pilih II (AutoSave/Simpan/Simpan dan Kirim/Batal Simpan/Batal Simpan dan Kirim) | N1: Pilih III (AutoSave/Simpan/Simpan dan Kirim/Batal Simpan/Batal Simpan dan Kirim)
A2: 1 | B2: lorem | C2: \\10.5.180.227\Source\bca.jpg | D2: https://vidio.com | E2: 063/SE/POL/2018;063/SE/POL/2019 | F2: Pembukuan;Customer Relationship | H2: NANDA FEBY RAHMADANI LUBIS | I2: Artikel - Supereditor u068843 | J2: Tidak | K2: Tidak | L2: Simpan dan Kirim
A3: 2 | B3: lorem | C3: \\10.5.180.227\Source\bca.jpg | D3: https://vidio.com | E3: 063/SE/POL/2018;063/SE/POL/2019 | F3: Pembukuan;Customer Relationship | H3: NANDA FEBY RAHMADANI LUBIS | I3: Artikel - Supereditor u068843 | J3: Tidak | K3: Tidak | L3: Simpan dan Kirim
A4: 3 | B4: lorem | C4: \\10.5.180.227\Source\bca.jpg | D4: https://vidio.com | E4: 063/SE/POL/2018;063/SE/POL/2019 | F4: Pembukuan | H4: NANDA FEBY RAHMADANI LUBIS | I4: VP - Supereditor u068843 | J4: Tidak | K4: Tidak | L4: Simpan dan Kirim
A5: 4 | B5: lorem | E5: 063/SE/POL/2018 | H5: NANDA FEBY RAHMADANI LUBIS | I5: VP - Supereditor u068843 | J5: Tidak | K5: Tidak | L5: Simpan dan Kirim
A6: 5 | B6: lorem | C6: \\10.5.180.227\Source\bca.jpg | D6: https://vidio.com | E6: 063/SE/POL/2018;063/SE/POL/2019 | F6: Pembukuan;Customer Relationship | H6: NANDA FEBY RAHMADANI LUBIS | I6: Artikel - Supereditor u068843 | J6: Tidak | K6: Tidak | L6: Simpan
A7: 6 | B7: lorem | C7: \\10.5.180.227\Source\bca.jpg | D7: https://vidio.com | E7: 063/SE/POL/2018;063/SE/POL/2019 | F7: Pembukuan;Customer Relationship | H7: NANDA FEBY RAHMADANI LUBIS | I7: Artikel - Supereditor u068843 | J7: Tidak | K7: Tidak | L7: Simpan
A8: 7 | B8: lorem | C8: \\10.5.180.227\Source\bca.jpg | D8: https://vidio.com | E8: 063/SE/POL/2018;063/SE/POL/2019 | F8: Pembukuan | H8: NANDA FEBY RAHMADANI LUBIS | I8: VP - Supereditor u068843 | J8: Tidak | K8: Tidak | L8: Simpan
A9: 8 | B9: lorem | E9: 063/SE/POL/2018 | H9: NANDA FEBY RAHMADANI LUBIS | I9: VP - Supereditor u068843 | J9: Tidak | K9: Tidak | L9: Simpan
A10: 9 | B10: lorem | C10: \\10.5.180.227\Source\bca.jpg | D10: https://vidio.com | E10: 063/SE/POL/2018;063/SE/POL/2019 | F10: Pembukuan;Customer Relationship | H10: FEBRIANTY DANUS | I10: Artikel - Publisher U543390 | J10: Tidak | K10: Tidak | L10: Simpan dan Kirim
A11: 10 | B11: lorem | C11: \\10.5.180.227\Source\bca.jpg | D11: https://vidio.com | E11: 063/SE/POL/2018;063/SE/POL/2019 | F11: Pembukuan;Customer Relationship | H11: FEBRIANTY DANUS | I11: Artikel - Publisher U543390 | J11: Tidak | K11: Tidak | L11: Simpan dan Kirim
A12: 11 | B12: lorem | C12: \\10.5.180.227\Source\bca.jpg | D12: https://vidio.com | E12: 063/SE/POL/2018;063/SE/POL/2019 | F12: Pembukuan | H12: FEBRIANTY DANUS | I12: VP - Publisher U543390 | J12: Tidak | K12: Tidak | L12: Simpan dan Kirim
A13: 12 | B13: lorem | E13: 063/SE/POL/2018 | H13: FEBRIANTY DANUS | I13: VP - Publisher U543390 | J13: Tidak | K13: Tidak | L13: Simpan dan Kirim
A14: 13 | B14: lorem | C14: \\10.5.180.227\Source\bca.jpg | D14: https://vidio.com | E14: 063/SE/POL/2018;063/SE/POL/2019 | F14: Pembukuan;Customer Relationship | H14: FEBRIANTY DANUS | I14: Artikel - Publisher U543390 | J14: Tidak | K14: Tidak | L14: Simpan
A15: 14 | B15: lorem | C15: \\10.5.180.227\Source\bca.jpg | D15: https://vidio.com | E15: 063/SE/POL/2018;063/SE/POL/2019 | F15: Pembukuan;Customer Relationship | H15: FEBRIANTY DANUS | I15: Artikel - Publisher U543390 | J15: Tidak | K15: Tidak | L15: Simpan
A16: 15 | B16: lorem | C16: \\10.5.180.227\Source\bca.jpg | D16: https://vidio.com | E16: 063/SE/POL/2018;063/SE/POL/2019 | F16: Pembukuan | H16: FEBRIANTY DANUS | I16: VP - Publisher U543390 | J16: Tidak | K16: Tidak | L16: Simpan
A17: 16 | B17: lorem | E17: 063/SE/POL/2018 | H17: FEBRIANTY DANUS | I17: VP - Publisher U543390 | J17: Tidak | K17: Tidak | L17: Simpan
A18: 62 | B18: lorem | C18: \\10.5.180.227\Source\bca.jpg | D18: https://vidio.com | E18: 063/SE/POL/2018;063/SE/POL/2019 | F18: Pembukuan | H18: FEBRIANTY DANUS | I18: VP - Publisher U543390 | J18: Tidak | K18: Tidak | L18: Simpan
A19: 63 | B19: lorem | E19: 063/SE/POL/2018 | H19: FEBRIANTY DANUS | I19: VP - Publisher U543390 | J19: Tidak | K19: Tidak | L19: Simpan
A20: 64 | B20: lorem | C20: \\10.5.180.227\Source\bca.jpg | D20: https://vidio.com | E20: 063/SE/POL/2018;063/SE/POL/2019 | F20: Pembukuan;Customer Relationship | H20: FEBRIANTY DANUS | I20: Artikel - Publisher U543390 | J20: Tidak | K20: Tidak | L20: Simpan
A21: 65 | B21: lorem | C21: \\10.5.181.225\Source\bca.jpg | D21: https://vidio.com | E21: 063/SE/POL/2018;063/SE/POL/2019 | F21: Pembukuan;Customer Relationship | H21: FEBRIANTY DANUS | I21: Artikel - Publisher U543390 | J21: Tidak | K21: Tidak | L21: Simpan

Sheet Data Edit Isi Artikel VP
A1: NO | B1: NAMA Artikel 04062025/ACCORDION EDIT | C1: EDIT JUDUL Artikel 04062025 | D1: DESKRIPSI SINGKAT | E1: PATH FILE GAMBAR | F1: URL VIDEO | G1: URL VIDEO 2 | H1: SK/SE REFERENSI | I1: HAPUS SK/SE | J1: INFORMASI TERKAIT | K1: SUGGESTION | L1: SIMPAN DAN KIRIM | M1: CATATAN SIMPAN & KIRIM | N1: Preview (Ya/Tidak) | O1: Riwayat Versi (Ya/Tidak) | P1: Pilih (AutoSave/Simpan/Simpan dan Kirim/Batal Simpan/Batal Simpan dan Kirim) | Q1: Pilih II (AutoSave/Simpan/Simpan dan Kirim/Batal Simpan/Batal Simpan dan Kirim) | R1: Pilih III (AutoSave/Simpan/Simpan dan Kirim/Batal Simpan/Batal Simpan dan Kirim)
A2: 5 | B2: Tambah Ubah Approved Super Editor Artikel 04062025 E | C2: Ubah Tambah Ubah Approved Super Editor Artikel 04062025 E | D2: Ubah lorem | E2: \\10.5.180.227\Source\bca.jpg | F2: https://vidio.com | H2: 063/SE/POL/2018;063/SE/POL/2019 | J2: Pembukuan;Customer Relationship | L2: NANDA FEBY RAHMADANI LUBIS | M2: Artikel - Supereditor u068843 | N2: Tidak | O2: Tidak | P2: Simpan dan Kirim
A3: 6 | B3: Tambah Ubah Reject Super Editor Artikel 04062025 F | C3: Ubah Tambah Ubah Reject Super Editor Artikel 04062025 F | D3: Ubah lorem | E3: \\10.5.180.227\Source\bca.jpg | F3: https://vidio.com | H3: 063/SE/POL/2018;063/SE/POL/2019 | J3: Pembukuan;Customer Relationship | L3: NANDA FEBY RAHMADANI LUBIS | M3: Artikel - Supereditor u068843 | N3: Tidak | O3: Tidak | P3: Simpan dan Kirim
A4: 7 | B4: Tambah Ubah Approved Super Editor VP 04062025 G | C4: Ubah Tambah Ubah Approved Super Editor VP 04062025 G | D4: Ubah lorem | E4: \\10.5.180.227\Source\bca.jpg | F4: https://vidio.com | H4: 063/SE/POL/2018;063/SE/POL/2019 | J4: Pembukuan;Customer Relationship | L4: NANDA FEBY RAHMADANI LUBIS | M4: Artikel - Supereditor u068843 | N4: Tidak | O4: Tidak | P4: Simpan dan Kirim
A5: 8 | B5: Tambah Ubah Reject Super Editor VP 04062025 H | C5: Ubah Tambah Ubah Reject Super Editor VP 04062025 H | D5: Ubah lorem | H5: 063/SE/POL/2018 | L5: NANDA FEBY RAHMADANI LUBIS | M5: Artikel - Supereditor u068843 | N5: Tidak | O5: Tidak | P5: Simpan dan Kirim
A6: 13 | B6: Tambah Ubah Approved Publisher Artikel 04062025 M | C6: Ubah Tambah Ubah Approved Publisher Artikel 04062025 M | D6: Ubah lorem | E6: \\10.5.180.227\Source\bca.jpg | F6: https://myvideo.bca.co.id/embed/4huDORkHGx631d1 | H6: 063/SE/POL/2018;063/SE/POL/2019 | J6: Pembukuan;Customer Relationship | L6: FEBRIANTY DANUS | M6: Artikel - Publisher U543390 | N6: Tidak | O6: Tidak | P6: Simpan dan Kirim
A7: 14 | B7: Tambah Ubah Reject Publisher Artikel 04062025 N | C7: Ubah Tambah Ubah Reject Publisher Artikel 04062025 N | D7: Ubah lorem | E7: \\10.5.180.227\Source\bca.jpg | F7: https://vidio.com | H7: 063/SE/POL/2018;063/SE/POL/2019 | J7: Pembukuan;Customer Relationship | L7: FEBRIANTY DANUS | M7: Artikel - Publisher U543390 | N7: Tidak | O7: Tidak | P7: Simpan dan Kirim
A8: 15 | B8: Tambah Ubah Approved Publisher VP 04062025 O | C8: Ubah Tambah Ubah Approved Publisher VP 04062025 O | D8: Ubah lorem | E8: \\10.5.180.227\Source\bca.jpg | F8: https://vidio.com | H8: 063/SE/POL/2018;063/SE/POL/2019 | J8: Pembukuan;Customer Relationship | L8: FEBRIANTY DANUS | M8: VP - Publisher U543390 | N8: Tidak | O8: Tidak | P8: Simpan dan Kirim
A9: 16 | B9: Tambah Ubah Reject Publisher VP 04062025 P | C9: Ubah Tambah Ubah Reject Publisher VP 04062025 P | D9: Ubah lorem | H9: 063/SE/POL/2018 | L9: FEBRIANTY DANUS | M9: VP - Publisher U543390 | N9: Tidak | O9: Tidak | P9: Simpan dan Kirim
A10: 17 | C10: Ubah Tambah Approved Super Editor Artikel 04062025 A | D10: Update lorem | L10: NANDA FEBY RAHMADANI LUBIS | M10: Artikel - Supereditor u068843 | N10: Tidak | O10: Tidak | P10: Simpan
A11: 18 | C11: Ubah Lagii Tambah Approved Super Editor Artikel 04062025 A | D11: Update lorem | L11: NANDA FEBY RAHMADANI LUBIS | M11: Artikel - Supereditor u068843 | N11: Tidak | O11: Tidak | P11: Simpan
A12: 19 | C12: Ubah Tambah Approved Super Editor VP 04062025 C | D12: Update lorem | L12: NANDA FEBY RAHMADANI LUBIS | M12: VP - Supereditor u068843 | N12: Tidak | O12: Tidak | P12: Simpan
A13: 20 | C13: Ubah Lagii Tambah Approved Super Editor VP 04062025 C | D13: Update lorem | L13: NANDA FEBY RAHMADANI LUBIS | M13: VP - Supereditor u068843 | N13: Tidak | O13: Tidak | P13: Simpan
A14: 21 | C14: Ubah Lagii Tambah Ubah Approved Super Editor Artikel 04062025 E | D14: Update lorem | L14: NANDA FEBY RAHMADANI LUBIS | M14: Artikel - Supereditor u068843 | N14: Ya | O14: Tidak | P14: Batal Simpan | Q14: Simpan
A15: 22 | C15: Ubah Tambah Ubah Approved Super Editor Artikel 04062025 E | D15: Update lorem | L15: NANDA FEBY RAHMADANI LUBIS | M15: Artikel - Supereditor u068843 | N15: Tidak | O15: Tidak | P15: Batal Simpan | Q15: Simpan
A16: 23 | C16: Ubah Lagii Tambah Ubah Approved Super Editor VP 04062025 G | D16: Update lorem | L16: NANDA FEBY RAHMADANI LUBIS | M16: VP - Supereditor u068843 | N16: Tidak | O16: Tidak | P16: Batal Simpan | Q16: Simpan
A17: 24 | C17: Ubah Tambah Ubah Approved Super Editor VP 04062025 G | D17: Update lorem | L17: NANDA FEBY RAHMADANI LUBIS | M17: VP - Supereditor u068843 | N17: Tidak | O17: Tidak | P17: Batal Simpan | Q17: Simpan
A18: 25 | C18: Ubah Tambah Approved Publisher Artikel 04062025 I | D18: Update lorem | L18: FEBRIANTY DANUS | M18: Artikel - Publisher U543390 | N18: Tidak | O18: Tidak | P18: Simpan
A19: 26 | C19: Ubah Lagii Tambah Approved Publisher Artikel 04062025 I | D19: Update lorem | L19: FEBRIANTY DANUS | M19: Artikel - Publisher U543390 | N19: Tidak | O19: Tidak | P19: Simpan
A20: 27 | C20: Ubah Tambah Approved Publisher VP 04062025 K | D20: Update lorem | L20: FEBRIANTY DANUS | M20: VP - Publisher U543390 | N20: Tidak | O20: Tidak | P20: Simpan
A21: 28 | C21: Ubah Lagii Tambah Approved Publisher VP 04062025 K | D21: Update lorem | L21: FEBRIANTY DANUS | M21: VP - Publisher U543390 | N21: Tidak | O21: Tidak | P21: Simpan
A22: 29 | C22: Ubah Lagii Tambah Ubah Approved Publisher Artikel 04062025 M | D22: Update lorem | L22: FEBRIANTY DANUS | M22: Artikel - Publisher U543390 | N22: Tidak | O22: Tidak | P22: Batal Simpan | Q22: Simpan
A23: 30 | C23: Ubah Tambah Ubah Approved Publisher Artikel 04062025 M | D23: Update lorem | L23: FEBRIANTY DANUS | M23: Artikel - Publisher U543390 | N23: Tidak | O23: Tidak | P23: Batal Simpan | Q23: Simpan
A24: 31 | C24: Ubah Lagii Tambah Ubah Approved Publisher VP 04062025 O | D24: Update lorem | L24: FEBRIANTY DANUS | M24: VP - Publisher U543390 | N24: Tidak | O24: Tidak | P24: Batal Simpan | Q24: Simpan
A25: 32 | C25: Ubah Tambah Ubah Approved Publisher VP 04062025 O | D25: Update lorem | L25: FEBRIANTY DANUS | M25: VP - Publisher U543390 | N25: Tidak | O25: Tidak | P25: Batal Simpan | Q25: Simpan
A26: 62 | B26: Tambah Ubah Approved VP 04062025 Q Publisher Pop Up | C26: Ubah Tambah Ubah Approved VP 04062025 Q Publisher Pop Up | D26: Ubah lorem | L26: FEBRIANTY DANUS | M26: VP - Publisher U543390 | N26: Tidak | O26: Tidak | P26: Simpan dan Kirim
A27: 63 | B27: Tambah Ubah Reject VP 04062025 R Publisher Pop Up | C27: Ubah Tambah Ubah Reject VP 04062025 R Publisher Pop Up | D27: Ubah lorem | H27: 063/SE/POL/2018;063/SE/POL/2019 | L27: FEBRIANTY DANUS | M27: VP - Publisher U543390 | N27: Tidak | O27: Tidak | P27: Simpan dan Kirim
A28: 64 | B28: Tambah Ubah Approved Artikel 04062025 S Publisher Pop Up | C28: Ubah Tambah Ubah Approved Artikel 04062025 S Publisher Pop Up | D28: Ubah lorem | L28: FEBRIANTY DANUS | M28: Artikel - Publisher U543390 | N28: Tidak | O28: Tidak | P28: Simpan dan Kirim
A29: 65 | B29: Tambah Ubah Reject Artikel 04062025 T Publisher Pop Up | C29: Ubah Tambah Ubah Reject Artikel 04062025 T Publisher Pop Up | D29: Ubah lorem | L29: FEBRIANTY DANUS | M29: Artikel - Publisher U543390 | N29: Tidak | O29: Tidak | P29: Simpan dan Kirim
A30: 66 | B30: Penutupan Rekening | F30: https://myvideo.bca.co.id/embed/gTu5lrTGwKlr5d4 | G30: https://myvideo.bca.co.id/embed/9B76UhDfGesnR2G | L30: FEBRIANTY DANUS | N30: Tidak | O30: Tidak | P30: Simpan | Q30: Simpan dan Kirim
A31: 67 | B31: QRIS | F31: https://myvideo.bca.co.id/embed/gTu5lrTGwKlr5d4 | G31: https://myvideo.bca.co.id/embed/9B76UhDfGesnR2G | L31: FEBRIANTY DANUS | N31: Tidak | O31: Tidak | P31: Simpan | Q31: Simpan dan Kirim
A32: 68 | B32: QRIS | F32: https://myvideo.bca.co.id/embed/4huDORkHGx631d1 | G32: https://myvideo.bca.co.id/embed/gTu5lrTGwKlr5d4 | L32: FEBRIANTY DANUS | N32: Tidak | O32: Tidak | P32: Simpan | Q32: Simpan dan Kirim
A33: 69 | B33: Andrea | F33: https://myvideo.bca.co.id/embed/4huDORkHGx631d1 | G33: https://myvideo.bca.co.id/embed/9B76UhDfGesnR2G | L33: FEBRIANTY DANUS | N33: Tidak | O33: Tidak | P33: Simpan | Q33: Simpan dan Kirim
A34: 70 | B34: Penggunaan Media Sosial/Internet dan Email | F34: https://myvideo.bca.co.id/embed/4huDORkHGx631d1 | G34: https://myvideo.bca.co.id/embed/qoSfcXXyNTrLpTE | L34: FEBRIANTY DANUS | N34: Tidak | O34: Tidak | P34: Simpan | Q34: Simpan dan Kirim
A35: 71 | B35: Kerja Sama Sub Account | F35: https://myvideo.bca.co.id/embed/4huDORkHGx631d1 | G35: https://myvideo.bca.co.id/embed/9B76UhDfGesnR2G | L35: FEBRIANTY DANUS | N35: Tidak | O35: Tidak | P35: Simpan | Q35: Simpan dan Kirim
A36: 72 | B36: Ubah Lagii Tambah Ubah Approved Publisher Artikel 04062025 M | F36: https://myvideo.bca.co.id/embed/4huDORkHGx631d1 | G36: https://myvideo.bca.co.id/embed/3RQbQI3wbxlDgLM | L36: FEBRIANTY DANUS | N36: Tidak | O36: Tidak | P36: Simpan | Q36: Simpan dan Kirim
A37: 73 | B37: Penutupan Rekening | F37: https://myvideo.bca.co.id/embed/3RQbQI3wbxlDgLM | G37: https://myvideo.bca.co.id/embed/4huDORkHGx631d1 | L37: FEBRIANTY DANUS | N37: Tidak | O37: Tidak | P37: Simpan | Q37: Simpan dan Kirim
A38: 74 | B38: Penutupan Rekening | F38: https://myvideo.bca.co.id/embed/4huDORkHGx631d1 | G38: https://myvideo.bca.co.id/embed/3RQbQI3wbxlDgLM | L38: FEBRIANTY DANUS | N38: Tidak | O38: Tidak | P38: Simpan | Q38: Simpan dan Kirim
A39: 75 | B39: Ubah Lagii Tambah Ubah Approved Publisher Artikel 04062025 M | I39: 063/SE/POL/2018 | L39: FEBRIANTY DANUS | N39: Tidak | O39: Tidak | P39: Simpan
A40: 76 | B40: Ubah Lagii Tambah Ubah Approved Publisher Artikel 04062025 M | I40: 063/SE/POL/2019 | L40: FEBRIANTY DANUS | N40: Tidak | O40: Tidak | P40: Simpan

Sheet Data Tambah Topik Artikel VP
A1: NO | B1: JUDUL PARENT TOPIK | C1: JUDUL TOPIK | D1: ISI TOPIK | E1: Simpan (Ya/Tidak)
A2: 1 | C2: Ketentuan Tambah Approved Super Editor Artikel 04062025 A | D2: Isi Ketentuan artikel SE | E2: Ya
A3: 1 | C3: Formulir Tambah Approved Super Editor Artikel 04062025 A | D3: Isi Formulir artikel SE | E3: Ya
A4: 2 | C4: Ketentuan Tambah Reject Super Editor Artikel 04062025 B | D4: Isi Ketentuan artikel SE | E4: Ya
A5: 2 | C5: Formulir Tambah Reject Super Editor Artikel 04062025 B | D5: Isi Formulir artikel SE | E5: Ya
A6: 3 | C6: Ketentuan Tambah Approved Super Editor VP 04062025 C | D6: Isi Ketentuan artikel SE | E6: Ya
A7: 3 | C7: Formulir Tambah Approved Super Editor VP 04062025 C | D7: Isi Formulir artikel SE | E7: Ya
A8: 5 | C8: Ketentuan Tambah Ubah Approved Super Editor Artikel 04062025 E | D8: Isi Ketentuan artikel SE | E8: Ya
A9: 5 | C9: Formulir Tambah Ubah Approved Super Editor Artikel 04062025 E | D9: Isi Formulir artikel SE | E9: Ya
A10: 6 | C10: Ketentuan Tambah Ubah Reject Super Editor Artikel 04062025 F | D10: Isi Ketentuan artikel SE | E10: Ya
A11: 6 | C11: Formulir Tambah Ubah Reject Super Editor Artikel 04062025 F | D11: Isi Formulir artikel SE | E11: Ya
A12: 7 | C12: Ketentuan Tambah Ubah Approved Super Editor VP 04062025 G | D12: Isi Ketentuan artikel SE | E12: Ya
A13: 7 | C13: Formulir Tambah Ubah Approved Super Editor VP 04062025 G | D13: Isi Formulir artikel SE | E13: Ya
... A31: 65 | C31: Formulir Tambah Ubah Reject Artikel 04062025 T Publisher Pop Up | D31: Isi Formulir artikel P | E31: Ya

Sheet Data Artikel VP
A1: NO | B1: JUDUL ARTIKEL | C1: DESKRIPSI SINGKAT | D1: PATH FILE GAMBAR | E1: URL VIDEO | F1: SK/SE REFERENSI | G1: INFORMASI TERKAIT | H1: SUGGESTION | I1: SIMPAN DAN KIRIM | J1: CATATAN SIMPAN & KIRIM | K1: DURASI WAIT | L1: ACTION AFTER 1 | M1: ACTION AFTER 2 | N1: ACTION AFTER 3 | O1: ACTION AFTER 4 | P1: ACTION AFTER 5
A2: 1 | L2: Simpan
A3: 2 | L3: Simpan
A4: 3 | L4: Simpan
A5: 4 | B5: Coba tambah artikel Publisher 1 ubah | C5: lorem lorem Hyperlink Ubah | E5: https://vidio-ubah.com | F5: 063/SE/POL/2018 | G5: Customer Relationship | H5: Penanganan Pengaduan Nasabah;Pengenalan Nasabah | I5: RADITIA FEBIYANTO | J5: Artikel - Editor u060242 | L5: Simpan
A6: 5 | I6: RADITIA FEBIYANTO | J6: Artikel - Editor u060242 | L6: Simpan
A7: 6 | C7: lorem | D7: \\10.5.180.227\Source\bca.jpg | E7: https://vidio.com | F7: 063/SE/POL/2018;063/SE/POL/2019 | G7: Pembukuan;Customer Relationship | I7: RADITIA FEBIYANTO | J7: Artikel - Editor u060242 | L7: Simpan
A8: 7 | C8: lorem | D8: \\10.5.180.227\Source\bca.jpg | E8: https://vidio.com | F8: 063/SE/POL/2018;063/SE/POL/2019 | G8: Pembukuan;Customer Relationship | I8: RADITIA FEBIYANTO | J8: Artikel - Editor u060242 | L8: Simpan
A9: 8 | C9: lorem | D9: \\10.5.180.227\Source\bca.jpg | E9: https://vidio.com | F9: 063/SE/POL/2018;063/SE/POL/2019 | G9: Pembukuan;Customer Relationship | I9: SAMUEL MARANOW | J9: Artikel - Editor u060242 | L9: Simpan
A10: 9 | I10: RADITIA FEBIYANTO | J10: Artikel - Editor u060242 | L10: Simpan
A11: 10 | L11: Simpan
A12: 11 | L12: Simpan
A13: 12 | L13: Simpan
A14: 13 | L14: Simpan
A15: 14 | L15: Simpan
A16: 15 | L16: Simpan
A17: 16 | L17: Simpan
A18: 17 | L18: Simpan
A19: 18 | L19: Simpan
A20: 19 | L20: Simpan
A21: 20 | L21: Simpan
A22: 21 | L22: Simpan
A23: 25 | K23: 10 | L23: Keluar

Sheet Data Hapus Accordion
A1: NO | B1: JUDUL TOPIK | C1: Hapus Accordion (Yes/No)

Sheet Data Edit Topik Artikel VP
A1: NO | B1: JUDUL PARENT TOPIK | C1: JUDUL TOPIK | D1: ISI TOPIK | E1: Simpan (Ya/Tidak)
A2: 17 | B2: Ketentuan Ubah Tambah Approved Super Editor Artikel 04062025 A | C2: Coba Sub | D2: Isi Ketentuan artikel Super Editor

Sheet Data Approve Artikel
A1: NO | B1: NAMA Artikel 04062025 | C1: PILIH | D1: TANGGAL | E1: MY PAGES (draft/pending/approved) | F1: JENIS DOKUMEN | G1: SK/SE REFERENSI | H1: NO DOKUMEN | I1: CATATAN | J1: Approve (Ya/Tidak) | K1: USERNAME SKSE | L1: PASSWORD SKSE
A2: 1 | B2: Tambah Approved Super Editor Artikel 04062025 A | E2: draft | F2: Dokumen Lainnya | H2: 101 | I2: Approve My Pages Draft Dokumen | J2: Ya | K2: u064959 | L2: erickoo087
A3: 3 | B3: Tambah Approved Super Editor VP 04062025 C | E3: draft | F3: SK/SE | G3: 063/SE/POL/2018;063/SE/POL/2019 | J3: Ya | K3: u064959 | L3: erickoo087
A4: 5 | B4: Ubah Tambah Ubah Approved Super Editor Artikel 04062025 E | E4: draft | F4: Dokumen Lainnya | H4: 102 | I4: Approve My Pages Draft Dokumen | J4: Ya | K4: u064959 | L4: erickoo087
A5: 7 | B5: Ubah Tambah Ubah Approved Super Editor VP 04062025 G | E5: draft | F5: SK/SE | G5: 063/SE/POL/2018;063/SE/POL/2019 | J5: Ya | K5: u064959 | L5: erickoo087
A6: 9 | B6: Tambah Approved Publisher Artikel 04062025 I | E6: pending | F6: Dokumen Lainnya | H6: 103 | I6: Approve My Pages Draft Dokumen | J6: Ya | K6: u064959 | L6: erickoo087
A7: 11 | B7: Tambah Approved Publisher VP 04062025 K | E7: pending | F7: SK/SE | G7: 063/SE/POL/2018;063/SE/POL/2019 | J7: Ya | K7: u064959 | L7: erickoo087
A8: 13 | B8: Ubah Tambah Ubah Approved Publisher Artikel 04062025 M | E8: pending | F8: Dokumen Lainnya | H8: 104 | I8: Approve My Pages Draft Dokumen | J8: Ya | K8: u064959 | L8: erickoo087
A9: 15 | B9: Ubah Tambah Ubah Approved Publisher VP 04062025 O | E9: pending | F9: SK/SE | G9: 063/SE/POL/2018;063/SE/POL/2019 | J9: Ya | K9: u064959 | L9: erickoo087
A10: 17 | B10: Ubah Tambah Approved Super Editor Artikel 04062025 A | E10: draft | F10: SK/SE | G10: 063/SE/POL/2018 | J10: Ya | K10: u064959 | L10: erickoo087
A11: 19 | B11: Ubah Tambah Approved Super Editor VP 04062025 C | E11: draft | F11: SK/SE | G11: 063/SE/POL/2018 | J11: Ya | K11: u064959 | L11: erickoo087
A12: 21 | B12: Ubah Lagii Tambah Ubah Approved Super Editor Artikel 04062025 E | E12: draft | F12: SK/SE | G12: 063/SE/POL/2018 | J12: Ya | K12: u064959 | L12: erickoo087
A13: 23 | B13: Ubah Lagii Tambah Ubah Approved Super Editor VP 04062025 G | E13: draft | F13: SK/SE | G13: 063/SE/POL/2018 | J13: Ya | K13: u064959 | L13: erickoo087
A14: 25 | B14: Ubah Tambah Approved Publisher Artikel 04062025 I | E14: pending | F14: SK/SE | G14: 063/SE/POL/2018 | J14: Ya | K14: u064959 | L14: erickoo087
A15: 27 | B15: Ubah Tambah Approved Publisher VP 04062025 K | E15: pending | F15: SK/SE | G15: 063/SE/POL/2018 | J15: Ya | K15: u064959 | L15: erickoo087
A16: 29 | B16: Ubah Lagii Tambah Ubah Approved Publisher Artikel 04062025 M | E16: pending | F16: SK/SE | G16: 063/SE/POL/2018 | J16: Ya | K16: u064959 | L16: erickoo087
A17: 31 | B17: Ubah Lagii Tambah Ubah Approved Publisher VP 04062025 O | E17: pending | F17: SK/SE | G17: 063/SE/POL/2018 | J17: Ya | K17: u064959 | L17: erickoo087
A18: 53 | B18: Ubah Tambah Ubah Approved Super Editor Artikel 04062025 E | E18: draft | F18: SK/SE | G18: 063/SE/POL/2018 | J18: Ya | K18: u064959 | L18: erickoo087
A19: 54 | B19: Ubah Tambah Ubah Approved Publisher Artikel 04062025 M | E19: pending | F19: SK/SE | G19: 063/SE/POL/2018 | J19: Ya | K19: u064959 | L19: erickoo087
A20: 55 | B20: Ubah Tambah Ubah Approved Publisher Artikel 04062025 M | E20: pending | F20: SK/SE | G20: 063/SE/POL/2018 | J20: Ya | K20: u064959 | L20: erickoo087
A21: 60 | B21: Ubah Tambah Approved Publisher Artikel 04062025 I | F21: Dokumen Lainnya | H21: 103 | I21: Approve My Pages Draft Dokumen | J21: Ya | K21: u064959 | L21: erickoo087
A22: 62 | B22: Tambah Ubah Approved VP 04062025 Q Publisher Pop Up | E22: pending | F22: Dokumen Lainnya | H22: 103 | I22: Approve My Pages Draft Dokumen | J22: Ya | K22: u064959 | L22: erickoo087
A23: 64 | B23: Tambah Ubah Approved Artikel 04062025 S Publisher Pop Up | E23: pending | F23: SK/SE | G23: 063/SE/POL/2018;063/SE/POL/2019 | J23: Ya | K23: u064959 | L23: erickoo087
A24: 66 | B24: Penutupan Rekening | E24: pending | F24: Dokumen Lainnya | H24: 103 | I24: Approve Dokumen | J24: Ya | K24: u064959 | L24: erickoo087
A25: 67 | B25: QRIS | E25: pending | F25: SK/SE | G25: 063/SE/POL/2018 | J25: Ya | K25: u064959 | L25: erickoo087
A26: 68 | B26: QRIS | E26: pending | F26: Dokumen Lainnya | H26: 104 | I26: Approve Dokumen | J26: Ya | K26: u064959 | L26: erickoo087
A27: 69 | B27: ANDREA | E27: pending | F27: Dokumen Lainnya | H27: 104 | I27: Approve Dokumen | J27: Ya | K27: u064959 | L27: erickoo087
A28: 70 | B28: Penggunaan Media Sosial/Internet dan Email | E28: pending | F28: Dokumen Lainnya | H28: 105 | I28: Approve Dokumen | J28: Ya | K28: u064959 | L28: erickoo087
A29: 71 | B29: Kerja Sama Sub Account | E29: pending | F29: SK/SE | G29: 063/SE/POL/2020 | J29: Ya | K29: u064959 | L29: erickoo087
A30: 72 | B30: Ubah Lagii Tambah Ubah Approved Publisher Artikel 04062025 M | E30: pending | F30: SK/SE | G30: 063/SE/POL/2020 | J30: Ya | K30: u064959 | L30: erickoo087
A31: 73 | B31: Ubah Lagii Tambah Ubah Approved Publisher Artikel 04062025 M | E31: pending | F31: SK/SE | G31: 063/SE/POL/2019 | J31: Ya | K31: u064959 | L31: erickoo087
A32: 75 | B32: Ubah Lagii Tambah Ubah Approved Publisher Artikel 04062025 M | E32: pending | F32: Dokumen Lainnya | H32: 105 | I32: Approve Dokumen | J32: Ya | K32: u064959 | L32: erickoo087

Sheet Data Reject Artikel
A1: NO | B1: NAMA Artikel 04062025 | C1: PILIH | D1: TANGGAL | E1: MY PAGES (draft/pending) | F1: CATATAN REJECT | G1: Reject (Ya/Tidak) | H1: USERNAME SKSE | I1: PASSWORD SKSE
A2: 2 | B2: Tambah Reject Super Editor Artikel 04062025 B | E2: draft | F2: Reject Tambah Artikel | G2: Ya | H2: u064959 | I2: erickoo087
A3: 4 | B3: Tambah Reject Super Editor VP 04062025 D | E3: draft | F3: Reject Tambah VP | G3: Ya | H3: u064959 | I3: erickoo087
A4: 6 | B4: Ubah Tambah Ubah Reject Super Editor Artikel 04062025 F | E4: draft | F4: Reject Tambah Artikel | G4: Ya | H4: u064959 | I4: erickoo087
A5: 8 | B5: Ubah Tambah Ubah Reject Super Editor VP 04062025 H | E5: draft | F5: Reject Tambah VP | G5: Ya | H5: u064959 | I5: erickoo087
A6: 10 | B6: Tambah Reject Publisher Artikel 04062025 J | E6: pending | F6: Reject Tambah Artikel | G6: Ya | H6: u064959 | I6: erickoo087
A7: 12 | B7: Tambah Reject Publisher VP 04062025 L | E7: pending | F7: Reject Tambah VP | G7: Ya | H7: u064959 | I7: erickoo087
A8: 14 | B8: Ubah Tambah Ubah Reject Publisher Artikel 04062025 N | E8: pending | F8: Reject Tambah Artikel | G8: Ya | H8: u064959 | I8: erickoo087
A9: 16 | B9: Ubah Tambah Ubah Reject Publisher VP 04062025 P | E9: pending | F9: Reject Tambah VP | G9: Ya | H9: u064959 | I9: erickoo087
A10: 18 | B10: Ubah Lagii Tambah Approved Super Editor Artikel 04062025 A | E10: draft | F10: Reject Ubah Artikel | G10: Ya | H10: u064959 | I10: erickoo087
A11: 20 | B11: Ubah Lagii Tambah Approved Super Editor VP 04062025 C | E11: draft | F11: Reject Ubah VP | G11: Ya | H11: u064959 | I11: erickoo087
A12: 22 | B12: Ubah Tambah Ubah Approved Super Editor Artikel 04062025 E | E12: draft | F12: Reject Ubah Artikel | G12: Ya | H12: u064959 | I12: erickoo087
A13: 24 | B13: Ubah Tambah Ubah Approved Super Editor VP 04062025 G | E13: draft | F13: Reject Ubah VP | G13: Ya | H13: u064959 | I13: erickoo087
... A28: 77 | B28: myBCA | E28: pending | F28: Reject Ubah VP | G28: Ya | H28: u064959 | I28: erickoo087
B30: Ubah Tambah Ubah Approved Artikel 04062025 S Publisher Pop Up

Sheet Tambah Approve Super Editor
A1: Testcase | B1: Is_Running | C1: Keyword | D1: Pagename | E1: ObjectName | F1: ObjectType | G1: Value | H1: Application
A2: Login A | B2: Yes | H2: PAKAR
C3: set_specific_wp | G3: Login Super Editor
C4: start_chrome_driver
C5: go_to_url | G5: =Datatable!$R$1 -> URL PAKAR
C6: wait_until_web_element_exist | E6: fieldUserID_pakar
C7: screenshot
C8: set_text | E8: fieldUserID_pakar | G8: =Datatable!$J$1 -> USER ID SUPER EDITOR A
C9: set_text | E9: fieldUserPassword_pakar | G9: =Datatable!$K$1 -> PASSWORD SUPER EDITOR A
C10: screenshot
C11: click | E11: btnSubmitLogin_pakar
A12: Tambah Artikel | B12: Yes | H12: PAKAR
C13: if_exist_go_to_value | E13: btnPelajariNanti_pakar | G13: PELAJARI NANTI
C14: anchor_go_to_value | G14: PELAJARI NANTI
C15: wait_until_web_element_exist | E15: btnPelajariNanti_pakar
C16: screenshot
C17: click | E17: btnPelajariNanti_pakar
C18: anchor_go_to_value | G18: END_IF_EXIST
C19: wait_for_seconds | G19: 2
C20: screenshot
C21: for_data_by_sheet | G21: Data Tambah Artikel VP;End Data Tambah Artikel VP
C22: click | E22: btnTambahHalaman_pakar
C23: go_to_value | G23: ='Data Tambah Artikel VP'!$B$1 -> PILIH (Artikel/Virtual Page)
C24: anchor_go_to_value | G24: Artikel
C25: wait_until_web_element_exist | E25: btnArtikelTbhHlm_pakar
C26: screenshot
C27: click | E27: btnArtikelTbhHlm_pakar
C28: set_text | E28: fieldNamaArtikel_pakar | G28: ='Data Tambah Artikel VP'!$C$1 -> NAMA Artikel 04062025 VP 04062025
C29: click | E29: btnLokasiArtikel_pakar
C30: wait_for_seconds | G30: 2
C31: click_lokasi | E31: btnLokasiArtikelLv1_pakar | G31: ='Data Tambah Artikel VP'!$E$1 -> LOKASI ARTIKEL VP
C32: click_replace | E32: rbtnTemplate_pakar | G32: ='Data Tambah Artikel VP'!$F$1 -> REKOMENDASI TEMPLATE
C33: wait_until_web_element_exist | E33: btnTambahArtikel_pakar
C34: screenshot
C35: click | E35: btnTambahArtikel_pakar
C36: go_to_value | G36: End Tambah
C37: anchor_go_to_value | G37: Virtual Page
C38: wait_until_web_element_exist | E38: btnVirtualPageHome_pakar
C39: screenshot
C40: click | E40: btnVirtualPageHome_pakar
...

Sheet Tambah Reject Super Editor
A1: Testcase | B1: Is_Running | C1: Keyword | D1: Pagename | E1: ObjectName | F1: ObjectType | G1: Value | H1: Application
A2: Login A | B2: Yes | H2: PAKAR
C3: set_specific_wp | G3: Login Super Editor
C4: start_chrome_driver
C5: go_to_url | G5: =Datatable!$R$1 -> URL PAKAR
C6: wait_until_web_element_exist | E6: fieldUserID_pakar
C7: screenshot
C8: set_text | E8: fieldUserID_pakar | G8: =Datatable!$J$1 -> USER ID SUPER EDITOR A
C9: set_text | E9: fieldUserPassword_pakar | G9: =Datatable!$K$1 -> PASSWORD SUPER EDITOR A
C10: screenshot
C11: click | E11: btnSubmitLogin_pakar
A12: Tambah Artikel | B12: Yes | H12: PAKAR
C13: if_exist_go_to_value | E13: btnPelajariNanti_pakar | G13: PELAJARI NANTI
C14: anchor_go_to_value | G14: PELAJARI NANTI
C15: wait_until_web_element_exist | E15: btnPelajariNanti_pakar
C16: screenshot
C17: click | E17: btnPelajariNanti_pakar
C18: anchor_go_to_value | G18: END_IF_EXIST
C19: wait_for_seconds | G19: 2
C20: screenshot
C21: for_data_by_sheet | G21: Data Tambah Artikel VP;End Data Tambah Artikel VP
C22: click | E22: btnTambahHalaman_pakar
C23: go_to_value | G23: ='Data Tambah Artikel VP'!$B$1 -> PILIH (Artikel/Virtual Page)
C24: anchor_go_to_value | G24: Artikel
C25: wait_until_web_element_exist | E25: btnArtikelTbhHlm_pakar
C26: screenshot
C27: click | E27: btnArtikelTbhHlm_pakar
C28: set_text | E28: fieldNamaArtikel_pakar | G28: ='Data Tambah Artikel VP'!$C$1 -> NAMA Artikel 04062025 VP 04062025
C29: click | E29: btnLokasiArtikel_pakar
C30: wait_for_seconds | G30: 2
C31: click_lokasi | E31: btnLokasiArtikelLv1_pakar | G31: ='Data Tambah Artikel VP'!$E$1 -> LOKASI ARTIKEL VP
C32: click_replace | E32: rbtnTemplate_pakar | G32: ='Data Tambah Artikel VP'!$F$1 -> REKOMENDASI TEMPLATE
C33: wait_until_web_element_exist | E33: btnTambahArtikel_pakar
C34: screenshot
C35: click | E35: btnTambahArtikel_pakar
C36: go_to_value | G36: End Tambah
C37: anchor_go_to_value | G37: Virtual Page
C38: wait_until_web_element_exist | E38: btnVirtualPageHome_pakar
C39: screenshot
C40: click | E40: btnVirtualPageHome_pakar
...

Sheet Tambah Approve Publisher
A1: Testcase | B1: Is_Running | C1: Keyword | D1: Pagename | E1: ObjectName | F1: ObjectType | G1: Value | H1: Application
A2: Login A | B2: Yes | H2: PAKAR
C3: set_specific_wp | G3: Login Super Editor
C4: start_chrome_driver
C5: go_to_url | G5: =Datatable!$R$1 -> URL PAKAR
C6: wait_until_web_element_exist | E6: fieldUserID_pakar
C7: screenshot
C8: set_text | E8: fieldUserID_pakar | G8: =Datatable!$J$1 -> USER ID SUPER EDITOR A
C9: set_text | E9: fieldUserPassword_pakar | G9: =Datatable!$K$1 -> PASSWORD SUPER EDITOR A
C10: screenshot
C11: click | E11: btnSubmitLogin_pakar
A12: Tambah Artikel | B12: Yes | H12: PAKAR
C13: if_exist_go_to_value | E13: btnPelajariNanti_pakar | G13: PELAJARI NANTI
C14: anchor_go_to_value | G14: PELAJARI NANTI
C15: wait_until_web_element_exist | E15: btnPelajariNanti_pakar
C16: screenshot
C17: click | E17: btnPelajariNanti_pakar
C18: anchor_go_to_value | G18: END_IF_EXIST
C19: wait_for_seconds | G19: 2
C20: screenshot
C21: for_data_by_sheet | G21: Data Tambah Artikel VP;End Data Tambah Artikel VP
C22: click | E22: btnTambahHalaman_pakar
C23: go_to_value | G23: ='Data Tambah Artikel VP'!$B$1 -> PILIH (Artikel/Virtual Page)
C24: anchor_go_to_value | G24: Artikel
C25: wait_until_web_element_exist | E25: btnArtikelTbhHlm_pakar
C26: screenshot
C27: click | E27: btnArtikelTbhHlm_pakar
C28: set_text | E28: fieldNamaArtikel_pakar | G28: ='Data Tambah Artikel VP'!$C$1 -> NAMA Artikel 04062025 VP 04062025
C29: click | E29: btnLokasiArtikel_pakar
C30: wait_for_seconds | G30: 2
C31: click_lokasi | E31: btnLokasiArtikelLv1_pakar | G31: ='Data Tambah Artikel VP'!$E$1 -> LOKASI ARTIKEL VP
C32: click_replace | E32: rbtnTemplate_pakar | G32: ='Data Tambah Artikel VP'!$F$1 -> REKOMENDASI TEMPLATE
C33: wait_until_web_element_exist | E33: btnTambahArtikel_pakar
C34: screenshot
C35: click | E35: btnTambahArtikel_pakar
C36: go_to_value | G36: End Tambah
C37: anchor_go_to_value | G37: Virtual Page
C38: wait_until_web_element_exist | E38: btnVirtualPageHome_pakar
C39: screenshot
C40: click | E40: btnVirtualPageHome_pakar
...

Sheet Tambah Reject Publisher
