Workbook

Sheet DATA_INFO
A1: Start Data | B1: End Data
A2: 1 | B2: 1

Sheet Datatable
A1: NO | B1: ACTION | C1: SCRIPT_ALIAS | D1: DATA | E1: SCENARIO | F1: USER ID READER | G1: PASSWORD READER | H1: USER ID EDITOR | I1: PASSWORD EDITOR | J1: USER ID SUPER EDITOR A | K1: PASSWORD SUPER EDITOR A | L1: USER ID SUPER EDITOR B | M1: PASSWORD SUPER EDITOR B | N1: USER ID PUBLISHER A | O1: PASSWORD PUBLISHER A | P1: USER ID PUBLISHER B | Q1: PASSWORD PUBLISHER B | R1: URL PAKAR | S1: TEST_GROUP | T1: STATUS | U1: KETERANGAN | W1: SUMMARY'S STAT | X1: SUMMARY'S PROGRESS(%) | Y1: TOTAL SCRIPT
A2: 1 | B2: Tambah Approve Super Editor | D2: Data A | E2: Tambah Approved Artikel ke Super Editor | F2: u064959 | G2: erickoo085 | H2: u080794 | I2: marciasdivinasto123 | J2: u065951 | K2: feb022025 | L2: u068843 | M2: lovemonth25 | N2: U541785 | O2: 21029842 | P2: U543390 | Q2: Farina2003 | R2: https://pilot-pakar.intra.bca.co.id/ | S2: AUTOMATIONTEST | T2: PASSED | W2: PASSED | X2: 100% | Y2: 1
A3: 2 | B3: Tambah Reject Super Editor | D3: Data B | E3: Tambah Reject Artikel ke Super Editor | F3: u064959 | G3: erickoo085 | H3: u080794 | I3: marciasdivinasto123 | J3: u065951 | K3: feb022025 | L3: u068843 | M3: lovemonth25 | N3: U541785 | O3: 21029842 | P3: U543390 | Q3: Farina2003 | R3: https://pilot-pakar.intra.bca.co.id/ | S3: AUTOMATIONTEST | W3: FAILED | X3: 0% | Y3: 0
A4: 3 | B4: Tambah Approve Super Editor | D4: Data C | E4: Tambah Approved VP ke Super Editor | F4: u064959 | G4: erickoo085 | H4: u080794 | I4: marciasdivinasto123 | J4: u065951 | K4: feb022025 | L4: u068843 | M4: lovemonth25 | N4: U541785 | O4: 21029842 | P4: U543390 | Q4: Farina2003 | R4: https://pilot-pakar.intra.bca.co.id/ | S4: AUTOMATIONTEST
A5: 4 | B5: Tambah Reject Super Editor | D5: Data D | E5: Tambah Reject VP ke Super Editor | F5: u064959 | G5: erickoo085 | H5: u080794 | I5: marciasdivinasto123 | J5: u065951 | K5: feb022025 | L5: u068843 | M5: lovemonth25 | N5: U541785 | O5: 21029842 | P5: U543390 | Q5: Farina2003 | R5: https://pilot-pakar.intra.bca.co.id/ | S5: AUTOMATIONTEST
A6: 5 | B6: Tambah Ubah Approve Super Editor | D6: Data E | E6: Tambah Ubah Approve Artikel ke Super Editor | F6: u064959 | G6: erickoo085 | H6: u080794 | I6: marciasdivinasto123 | J6: u065951 | K6: feb022025 | L6: u068843 | M6: lovemonth25 | N6: U541785 | O6: 21029842 | P6: U543390 | Q6: Farina2003 | R6: https://pilot-pakar.intra.bca.co.id/ | S6: AUTOMATIONTEST
A7: 6 | B7: Tambah Ubah Reject Super Editor | D7: Data F | E7: Tambah Ubah Reject Artikel ke Super Editor | F7: u064959 | G7: erickoo085 | H7: u080794 | I7: marciasdivinasto123 | J7: u065951 | K7: feb022025 | L7: u068843 | M7: lovemonth25 | N7: U541785 | O7: 21029842 | P7: U543390 | Q7: Farina2003 | R7: https://pilot-pakar.intra.bca.co.id/ | S7: AUTOMATIONTEST
A8: 7 | B8: Tambah Ubah Approve Super Editor | D8: Data G | E8: Tambah Ubah Approve VP ke Super Editor | F8: u064959 | G8: erickoo085 | H8: u080794 | I8: marciasdivinasto123 | J8: u065951 | K8: feb022025 | L8: u068843 | M8: lovemonth25 | N8: U541785 | O8: 21029842 | P8: U543390 | Q8: Farina2003 | R8: https://pilot-pakar.intra.bca.co.id/ | S8: AUTOMATIONTEST
A9: 8 | B9: Tambah Ubah Reject Super Editor | D9: Data H | E9: Tambah Ubah Reject VP ke Super Editor | F9: u064959 | G9: erickoo085 | H9: u080794 | I9: marciasdivinasto123 | J9: u065951 | K9: feb022025 | L9: u068843 | M9: lovemonth25 | N9: U541785 | O9: 21029842 | P9: U543390 | Q9: Farina2003 | R9: https://pilot-pakar.intra.bca.co.id/ | S9: AUTOMATIONTEST
A10: 9 | B10: Tambah Approve Publisher | D10: Data I | E10: Tambah Approved Artikel ke Publisher | F10: u064959 | G10: erickoo085 | H10: u080794 | I10: marciasdivinasto123 | J10: u065951 | K10: feb022025 | L10: u068843 | M10: lovemonth25 | N10: U541785 | O10: 21029842 | P10: U543390 | Q10: Farina2003 | R10: https://pilot-pakar.intra.bca.co.id/ | S10: AUTOMATIONTEST
A11: 10 | B11: Tambah Reject Publisher | D11: Data J | E11: Tambah Reject Artikel ke Publisher | F11: u064959 | G11: erickoo085 | H11: u080794 | I11: marciasdivinasto123 | J11: u065951 | K11: feb022025 | L11: u068843 | M11: lovemonth25 | N11: U541785 | O11: 21029842 | P11: U543390 | Q11: Farina2003 | R11: https://pilot-pakar.intra.bca.co.id/ | S11: AUTOMATIONTEST
A12: 11 | B12: Tambah Approve Publisher | D12: Data K | E12: Tambah Approved VP ke Publisher | F12: u064959 | G12: erickoo085 | H12: u080794 | I12: marciasdivinasto123 | J12: u065951 | K12: feb022025 | L12: u068843 | M12: lovemonth25 | N12: U541785 | O12: 21029842 | P12: U543390 | Q12: Farina2003 | R12: https://pilot-pakar.intra.bca.co.id/ | S12: AUTOMATIONTEST
A13: 12 | B13: Tambah Reject Publisher | D13: Data L | E13: Tambah Reject VP ke Publisher | F13: u064959 | G13: erickoo085 | H13: u080794 | I13: marciasdivinasto123 | J13: u065951 | K13: feb022025 | L13: u068843 | M13: lovemonth25 | N13: U541785 | O13: 21029842 | P13: U543390 | Q13: Farina2003 | R13: https://pilot-pakar.intra.bca.co.id/ | S13: AUTOMATIONTEST
A14: 13 | B14: Tambah Ubah Approve Publisher | D14: Data M | E14: Tambah Ubah Approve Artikel ke Publisher | F14: u064959 | G14: erickoo085 | H14: u080794 | I14: marciasdivinasto123 | J14: u065951 | K14: feb022025 | L14: u068843 | M14: lovemonth25 | N14: U541785 | O14: 21029842 | P14: U543390 | Q14: Farina2003 | R14: https://pilot-pakar.intra.bca.co.id/ | S14: AUTOMATIONTEST
A15: 14 | B15: Tambah Ubah Reject Publisher | D15: Data N | E15: Tambah Ubah Reject Artikel ke Publisher | F15: u064959 | G15: erickoo085 | H15: u080794 | I15: marciasdivinasto123 | J15: u065951 | K15: feb022025 | L15: u068843 | M15: lovemonth25 | N15: U541785 | O15: 21029842 | P15: U543390 | Q15: Farina2003 | R15: https://pilot-pakar.intra.bca.co.id/ | S15: AUTOMATIONTEST
... A48: 47 | B48: Simpan dan Kirim Riwayat Versi | D48: Data A | E48: Simpan dan Kirim Riwayat Versi | F48: u064959 | G48: erickoo085 | H48: u080794 | I48: marciasdivinasto123 | J48: u065951 | K48: feb022025 | L48: u068843 | M48: lovemonth25 | N48: U541785 | O48: 21029842 | P48: U543390 | Q48: Farina2003 | R48: https://pilot-pakar.intra.bca.co.id/ | S48: AUTOMATIONTEST
A49: 48 | B49: Riwayat Versi Approved Super Ed | E49: Akses Riwayat Versi Approved Super Editor | F49: u064959 | G49: erickoo085 | H49: u080794 | I49: marciasdivinasto123 | J49: u065951 | K49: feb022025 | L49: u068843 | M49: lovemonth25 | N49: U541785 | O49: 21029842 | P49: U543390 | Q49: Farina2003 | R49: https://pilot-pakar.intra.bca.co.id/ | S49: AUTOMATIONTEST
A50: 49 | B50: Riwayat Versi Approved Publishe | E50: Akses Riwayat Versi Approved Publisher | F50: u064959 | G50: erickoo085 | H50: u080794 | I50: marciasdivinasto123 | J50: u065951 | K50: feb022025 | L50: u068843 | M50: lovemonth25 | N50: U541785 | O50: 21029842 | P50: U543390 | Q50: Farina2003 | R50: https://pilot-pakar.intra.bca.co.id/ | S50: AUTOMATIONTEST
A51: 50 | B51: Riwayat Versi Editor Approved P | E51: Akses Riwayat Versi Editor Approved Publisher | F51: u064959 | G51: erickoo085 | H51: u080794 | I51: marciasdivinasto123 | J51: u065951 | K51: feb022025 | L51: u068843 | M51: lovemonth25 | N51: U541785 | O51: 21029842 | P51: U543390 | Q51: Farina2003 | R51: https://pilot-pakar.intra.bca.co.id/ | S51: AUTOMATIONTEST
A52: 51 | B52: Hapus Approved | D52: Data A | E52: Hapus Approved Artikel/VP | F52: u064959 | G52: erickoo085 | H52: u080794 | I52: marciasdivinasto123 | J52: u065951 | K52: feb022025 | L52: u068843 | M52: lovemonth25 | N52: U541785 | O52: 21029842 | P52: U543390 | Q52: Farina2003 | R52: https://pilot-pakar.intra.bca.co.id/ | S52: AUTOMATIONTEST
A53: 52 | B53: Hapus Reject | D53: Data B | E53: Hapus Reject Artikel/VP | F53: u064959 | G53: erickoo085 | H53: u080794 | I53: marciasdivinasto123 | J53: u065951 | K53: feb022025 | L53: u068843 | M53: lovemonth25 | N53: U541785 | O53: 21029842 | P53: U543390 | Q53: Farina2003 | R53: https://pilot-pakar.intra.bca.co.id/ | S53: AUTOMATIONTEST
A54: 53 | B54: Tambah Kategori Menu | D54: Data D | E54: Tambah Kategori Menu | F54: u064959 | G54: erickoo085 | H54: u080794 | I54: marciasdivinasto123 | J54: u065951 | K54: feb022025 | L54: u068843 | M54: lovemonth25 | N54: U541785 | O54: 21029842 | P54: U543390 | Q54: Farina2003 | R54: https://pilot-pakar.intra.bca.co.id/ | S54: AUTOMATIONTEST
A55: 54 | B55: Ubah Kategori Menu | D55: Data D | E55: Ubah Kategori Menu | F55: u064959 | G55: erickoo085 | H55: u080794 | I55: marciasdivinasto123 | J55: u065951 | K55: feb022025 | L55: u068843 | M55: lovemonth25 | N55: U541785 | O55: 21029842 | P55: U543390 | Q55: Farina2003 | R55: https://pilot-pakar.intra.bca.co.id/ | S55: AUTOMATIONTEST
A56: 55 | B56: Hapus Kategori Menu | D56: Data D | E56: Hapus Kategori Menu | F56: u064959 | G56: erickoo085 | H56: u080794 | I56: marciasdivinasto123 | J56: u065951 | K56: feb022025 | L56: u068843 | M56: lovemonth25 | N56: U541785 | O56: 21029842 | P56: U543390 | Q56: Farina2003 | R56: https://pilot-pakar.intra.bca.co.id/ | S56: AUTOMATIONTEST
A57: 56 | B57: Assign Divisi | D57: Data D | E57: Assign Divisi | F57: u064959 | G57: erickoo085 | H57: u080794 | I57: marciasdivinasto123 | J57: u065951 | K57: feb022025 | L57: u068843 | M57: lovemonth25 | N57: U541785 | O57: 21029842 | P57: U543390 | Q57: Farina2003 | R57: https://pilot-pakar.intra.bca.co.id/ | S57: AUTOMATIONTEST

Sheet REPORT
A1: REPORT AUTOMATION
A4: NO | B4: DATATABLE NAME | C4: ACTION | D4: SCENARIO | E4: TEST_GROUP | F4: STATUS | G4: DESCRIPTION | H4: DURATION | J4: SUMMARY'S STAT | K4: SUMMARY'S PROGRESS(%) | L4: TOTAL SCRIPT | M4: TOTAL DURATION
A5: 1 | B5: DT FULL_REGRESI_PAKAR 1 | C5: Tambah Approve Super Editor | D5: Tambah Approved Artikel ke Super Editor | E5: AUTOMATIONTEST | F5: PASSED | H5: 00:04:44.914 | J5: PASSED | K5: 100% | L5: 1 | M5: 00:01:44.914
J6: FAILED | K6: 0% | L6: 0

Sheet Otomasi Pakar
A1: Testcase | B1: Is_Running | C1: Keyword | D1: Pagename | E1: ObjectName | F1: ObjectType | G1: Value | H1: Application
A2: ALL FITURE | B2: Yes | H2: PAKAR
C3: save_action | E3: [SAVE_ACTION_1] | G3: Login
C4: save_action | E4: [SAVE_ACTION_2] | G4: =Datatable!#REF! -> #REF!
C5: save_action | E5: [SAVE_ACTION_3] | G5: =Datatable!#REF! -> #REF!
C6: save_action | E6: [SAVE_ACTION_4] | G6: =Datatable!#REF! -> #REF!
C7: save_action | E7: [SAVE_ACTION_5] | G7: =Datatable!#REF! -> #REF!
C8: save_action | E8: [SAVE_ACTION_6] | G8: =Datatable!#REF! -> #REF!
C9: save_action | E9: [SAVE_ACTION_7] | G9: =Datatable!#REF! -> #REF!
C10: save_action | E10: [SAVE_ACTION_8] | G10: Logout
C11: read_script | G11: [SAVE_ACTION_#]

Sheet Data Script
A1: NO | B1: FEATURE
A2: 1 | B2: Login Editor
A3: 1 | B3: Tambah Artikel
A4: 1 | B4: Deskripsi Singkat
A5: 1 | B5: Tambah Gambar
A6: 1 | B6: Video Artikel
A7: 1 | B7: Tambah Ubah Topik
A8: 1 | B8: SK SE Referensi
A9: 1 | B9: Informasi Terkait
A10: 1 | B10: Simpan
A11: 1 | B11: Logout
A12: 2 | B12: Login Editor
A13: 2 | B13: Akses Artikel My Pages Draft
... A52: 7 | B52: Logout

Sheet Source
A1: Login Reader | B1: AutoSave | C1: Akses Artikel My Pages | D1: Akses Edit Halaman Artikel VP | E1: Tambah Artikel VP | F1: Copy Link Bookmark | H1: Akses Search Glossary | I1: Page Notifikasi - Closed | K1: Reader: | L1: Super Editor: | M1: Editor: | N1: Publisher: | O1: Pass Supereditor: | P1: Pass Publisher | S1: Tambah Artikel
A2: Login Editor | B2: Simpan | C2: Akses Artikel Contens | D2: Akses Edit Pop Up Notifikasi | E2: Edit Artikel VP | F2: Copy Link Bookmark Checkbox | H2: Akses Glossary Abjad | I2: Pop Up Notifikasi - Closed | K2: u076929 | L2: u066099 | M2: u060242 | N2: u541785 | O2: password | P2: password | S2: Tambah Judul
A3: Login Super Editor | B3: Simpan dan Kirim | C3: Akses Edit Page Notifikasi | D3: Batal Kirim Artikel | E3: Hapus Bookmark | H3: Ajukan Glossary | I3: Page Notifikasi - Waiting for User | K3: u064959 | L3: u053296 | M3: u059613 | N3: u067020 | O3: feb022025 | P3: 21029842 | S3: Deskripsi Singkat
A4: Login Publisher | B4: Batal Simpan | C4: Akses Edit My Pages Draft | D4: Batal Ubah Versi Artikel | E4: Hapus Bookmark Checkbox | H4: Akses Tab Glossary Main Search | I4: Pop Up Notifikasi - Waiting for User | L4: u065951 | M4: U555742 | N4: U541785 | O4: lovemonth25 | P4: Farina2003 | S4: Tambah Gambar
B5: Batal Simpan dan Kirim | C5: Akses Artikel Judul Feedback | D5: Akses Edit My Pages | E5: Pengecekan Tombol | L5: u068843 | N5: U543390 | S5: Video Artikel
B6: Preview | C6: Akses Artikel Isi Feedback | D6: Akses Edit Contens Artikel | E6: Reject My Pages | S6: Tambah Ubah Topik
B7: Kembali ke Halaman Editor | C7: Akses Artikel Page Notifikasi | D7: Akses Edit Contens Virtual Page | E7: Reject Page Notifikasi | S7: SK SE Referensi
B8: Riwayat Versi | C8: Akses Artikel Hyperlink Isi Art | D8: Akses Video Artikel | E8: Approve My Pages | S8: Informasi Terkait
B9: Keluar | C9: Akses Artikel Main Search | D9: Akses SKSE | E9: Approve Page Notifikasi | S9: Suggestion
B10: Batal Keluar | C10: Akses Artikel Burger Menu | E10: Sisipkan VP
C11: Akses Artikel Terbaru | E11: Akses Riwayat Versi
C12: Akses Artikel Rekomendasi | E12: Akses Riwayat Versi Reader
C13: Akses Artikel Page FAQ | E13: Unsisip VP
C14: Akses Artikel Isi FAQ | E14: Hapus Deskripsi
C15: Akses Artikel Bookmark PAKAR | E15: Hapus Artikel My Pages Draft
C16: Akses Artikel Link Glossary | E16: Hapus Artikel My Pages Approve
C17: Akses Artikel Informasi Terkait | E17: Hapus Artikel Contents Semua
C18: Akses Artikel Digunakan Oleh | E18: Hapus Artikel Contents Artikel
C19: Akses Video Artikel | E19: Hapus Artikel Contents VP
C20: Akses SKSE | E20: Tambah Hapus Bookmark Artikel
E21: Tambah Hapus Bookmark Akordion
E22: Copy Link Bookmark
E23: Hapus Single Bookmark
E24: Hapus Multiple Bookmark
E25: Akses Search Glossary
E26: Akses Glossary Abjad
E27: Akses Tab Glossary Main Search
E28: Ajukan Glossary
E29: Create Feedback
E30: Check Feedback Populer
E31: Feedback Sudah Baik
E32: Akses Dashboard Feedback
... E51: Checklist Kategori

Sheet Data Akses Artikel
A1: NO | B1: KATEGORI | C1: SUBKATEGORI | D1: MY PAGES (draft/pending/approved) | E1: CONTENTS (Semua/Artikel/Virtual Page) | F1: JUDUL_FAQ | G1: JUDUL_GLOSSARY | H1: INFORMASI_TERKAIT | I1: DIGUNAKAN_OLEH | J1: NAMA ARTIKEL (Didalam Folder pisahkan ;) | K1: TANGGAL | L1: USERNAME SKSE | M1: PASSWORD SKSE | N1: SK/SE
A2: 5 | D2: draft | J2: Tambah Ubah Approved Super Editor Artikel E | L2: u064959 | M2: erickoo085 | N2: 063/SE/POL/2018
A3: 6 | D3: draft | J3: Tambah Ubah Reject Super Editor Artikel F | L3: u064959 | M3: erickoo085 | N3: 063/SE/POL/2018
A4: 7 | D4: draft | J4: Tambah Ubah Approved Super Editor VP G | L4: u064959 | M4: erickoo085 | N4: 063/SE/POL/2018
A5: 8 | D5: draft | J5: Tambah Ubah Reject Super Editor VP H | L5: u064959 | M5: erickoo085 | N5: 063/SE/POL/2018
A6: 13 | D6: draft | J6: Tambah Ubah Approved Publisher Artikel M | L6: u064959 | M6: erickoo085 | N6: 063/SE/POL/2018
A7: 14 | D7: draft | J7: Tambah Ubah Reject Publisher Artikel N | L7: u064959 | M7: erickoo085 | N7: 063/SE/POL/2018
A8: 15 | D8: draft | J8: Tambah Ubah Approved Publisher VP O | L8: u064959 | M8: erickoo085 | N8: 063/SE/POL/2018
A9: 16 | D9: draft | J9: Tambah Ubah Reject Publisher VP P | L9: u064959 | M9: erickoo085 | N9: 063/SE/POL/2018
A10: 17 | J10: Tambah Approved Super Editor Artikel A
A11: 18 | J11: Tambah Reject Super Editor Artikel B
A12: 19 | J12: Tambah Approved Super Editor VP C
A13: 20 | J13: Tambah Reject Super Editor VP D
A14: 21 | J14: Ubah Tambah Ubah Approved Super Editor Artikel E
A15: 22 | J15: Ubah Tambah Ubah Reject Super Editor Artikel F
A16: 23 | J16: Ubah Tambah Ubah Approved Super Editor VP G
A17: 24 | J17: Ubah Tambah Ubah Reject Super Editor VP H
A18: 25
A19: 26
J22: Ubah Tambah Ubah Approved Publisher Artikel M
J23: Ubah Tambah Ubah Reject Publisher Artikel N
J24: Ubah Tambah Ubah Approved Publisher VP O
J25: Ubah Tambah Ubah Reject Publisher VP P
A36: 27 | J36: Pembukaan Rekening | K36: 22 Oktober 2024
A37: 28 | J37: artikel 22 | K37: 02 Agustus 2024
A38: 29 | J38: Vindi (Financial Diary) | K38: 13 Oktober 2022
A39: 30 | B39: Produk Untuk Nasabah | C39: Produk Digital | J39: Video Banking
A40: 31 | B40: Aktivitas Cabang | C40: Personel Operasional Cabang | J40: Admin Kredit;Admin Kredit
A41: 32 | J41: EDC
J42: VP - Kombinasi Tabel Edit
D43: draft | J43: Coba tambah artikel Lagi | K43: 09/12/2024 09:06 AM
D44: pending | J44: test tambah artikel | K44: 30/10/2024 09:48 AM
D45: approved | J45: artikel 5
E46: Semua | J46: BCA Dollar ubah | K46: 20/08/2024
E47: Artikel | J47: Artikel Coba Reksa dana
E48: Virtual Page | J48: Keputusan Pengajuan Naik Limit Kartu Kredit melalu

Sheet Data Akses Edit Artikel
A1: NO | B1: NAMA ARTIKEL (Didalam Folder pisahkan ;) | C1: MY PAGES (draft/pending/approved) | D1: PILIH | E1: TANGGAL
A2: 1 | B2: Artikel khusus sisip dan unsisip vp
A3: 2 | B3: Tes Export PDF
A4: 3 | B4: Tes Export PDF
A5: 8 | B5: EDC
A6: 9 | B6: EDC
A7: 7 | B7: Coba tambah artikel Publisher 1 ubah | E7: 29/08/2024
A8: 15 | B8: Coba tambah artikel Publisher 3 | E8: 29/08/2024
A9: 16 | B9: Coba tambah artikel Admin 1 | E9: 29/08/2024
A10: 27 | B10: Coba tambah artikel Admin | E10: 26/09/2024
A11: 25 | B11: Artikel khusus sisip dan unsisip vp
C27: draft
C28: pending
C29: approved

Sheet Data Tambah Artikel VP
A1: NO | B1: PILIH (Artikel/Virtual Page) | C1: NAMA ARTIKEL VP | D1: BENTUK VIRTUAL PAGE | E1: LOKASI ARTIKEL VP | F1: REKOMENDASI TEMPLATE
A2: 1 | B2: Artikel | C2: Tambah Approved Super Editor Artikel A | E2: Aktivitas Cabang;Pengelolaan Nasabah | F2: Basic
A3: 2 | B3: Artikel | C3: Tambah Reject Super Editor Artikel B | E3: Aktivitas Cabang;Pengelolaan Nasabah | F3: Basic
A4: 3 | B4: Virtual Page | C4: Tambah Approved Super Editor VP C | D4: Atribut Page | E4: Virtual Page;Atribut;Atribut Produk Digital | F4: Basic
A5: 4 | B5: Virtual Page | C5: Tambah Reject Super Editor VP D | D5: Micro Information | E5: Virtual Page;Atribut;Atribut Produk Digital
A6: 5 | B6: Artikel | C6: Tambah Ubah Approved Super Editor Artikel E | E6: Aktivitas Cabang;Pengelolaan Nasabah | F6: Basic
A7: 6 | B7: Artikel | C7: Tambah Ubah Reject Super Editor Artikel F | E7: Aktivitas Cabang;Pengelolaan Nasabah | F7: Basic
A8: 7 | B8: Virtual Page | C8: Tambah Ubah Approved Super Editor VP G | D8: Atribut Page | E8: Virtual Page;Atribut;Atribut Produk Digital | F8: Basic
A9: 8 | B9: Virtual Page | C9: Tambah Ubah Reject Super Editor VP H | D9: Micro Information | E9: Virtual Page;Atribut;Atribut Produk Digital
A10: 9 | B10: Artikel | C10: Tambah Approved Publisher Artikel I | E10: Aktivitas Cabang;Pengelolaan Nasabah | F10: Basic
A11: 10 | B11: Artikel | C11: Tambah Reject Publisher Artikel J | E11: Aktivitas Cabang;Pengelolaan Nasabah | F11: Basic
A12: 11 | B12: Virtual Page | C12: Tambah Approved Publisher VP K | D12: Atribut Page | E12: Virtual Page;Atribut;Atribut Produk Digital | F12: Basic
A13: 12 | B13: Virtual Page | C13: Tambah Reject Publisher VP L | D13: Micro Information | E13: Virtual Page;Atribut;Atribut Produk Digital
A14: 13 | B14: Artikel | C14: Tambah Ubah Approved Publisher Artikel M | E14: Aktivitas Cabang;Pengelolaan Nasabah | F14: Basic
A15: 14 | B15: Artikel | C15: Tambah Ubah Reject Publisher Artikel N | E15: Aktivitas Cabang;Pengelolaan Nasabah | F15: Basic
A16: 15 | B16: Virtual Page | C16: Tambah Ubah Approved Publisher VP O | D16: Atribut Page | E16: Virtual Page;Atribut;Atribut Produk Digital | F16: Basic
A17: 16 | B17: Virtual Page | C17: Tambah Ubah Reject Publisher VP P | D17: Micro Information | E17: Virtual Page;Atribut;Atribut Produk Digital

Sheet Data Tambah Isi Artikel VP
A1: NO | B1: DESKRIPSI SINGKAT | C1: PATH FILE GAMBAR | D1: URL VIDEO | E1: SK/SE REFERENSI | F1: INFORMASI TERKAIT | G1: SUGGESTION | H1: SIMPAN DAN KIRIM | I1: CATATAN SIMPAN & KIRIM | J1: Preview (Ya/Tidak) | K1: Riwayat Versi (Ya/Tidak) | L1: Pilih (AutoSave/Simpan/Simpan dan Kirim/Batal Simpan/Batal Simpan dan Kirim) | M1: Pilih II (AutoSave/Simpan/Simpan dan Kirim/Batal Simpan/Batal Simpan dan Kirim) | N1: Pilih III (AutoSave/Simpan/Simpan dan Kirim/Batal Simpan/Batal Simpan dan Kirim)
A2: 1 | B2: lorem lorem lorem | C2: \\10.5.180.227\Source\bca.jpg | D2: https://vidio.com | E2: 063/SE/POL/2018;063/SE/POL/2019 | F2: Pembukuan;Customer Relationship | H2: WENY ENJELIKA DOLOKSARIBU | I2: Artikel - Supereditor u068843 | J2: Tidak | K2: Tidak | L2: Simpan dan Kirim
A3: 2 | B3: lorem lorem lorem | C3: \\10.5.180.227\Source\bca.jpg | D3: https://vidio.com | E3: 063/SE/POL/2018;063/SE/POL/2019 | F3: Pembukuan;Customer Relationship | H3: WENY ENJELIKA DOLOKSARIBU | I3: Artikel - Supereditor u068843 | J3: Tidak | K3: Tidak | L3: Simpan dan Kirim
A4: 3 | B4: lorem lorem lorem | C4: \\10.5.180.227\Source\bca.jpg | D4: https://vidio.com | E4: 063/SE/POL/2018;063/SE/POL/2019 | F4: Pembukuan | H4: WENY ENJELIKA DOLOKSARIBU | I4: VP - Supereditor u068843 | J4: Tidak | K4: Tidak | L4: Simpan dan Kirim
A5: 4 | B5: lorem lorem lorem | E5: 063/SE/POL/2018 | H5: WENY ENJELIKA DOLOKSARIBU | I5: VP - Supereditor u068843 | J5: Tidak | K5: Tidak | L5: Simpan dan Kirim
A6: 5 | B6: lorem lorem lorem | C6: \\10.5.180.227\Source\bca.jpg | D6: https://vidio.com | E6: 063/SE/POL/2018;063/SE/POL/2019 | F6: Pembukuan;Customer Relationship | H6: WENY ENJELIKA DOLOKSARIBU | I6: Artikel - Supereditor u068843 | J6: Tidak | K6: Tidak | L6: Simpan
A7: 6 | B7: lorem lorem lorem | C7: \\10.5.180.227\Source\bca.jpg | D7: https://vidio.com | E7: 063/SE/POL/2018;063/SE/POL/2019 | F7: Pembukuan;Customer Relationship | H7: WENY ENJELIKA DOLOKSARIBU | I7: Artikel - Supereditor u068843 | J7: Tidak | K7: Tidak | L7: Simpan
A8: 7 | B8: lorem lorem lorem | C8: \\10.5.180.227\Source\bca.jpg | D8: https://vidio.com | E8: 063/SE/POL/2018;063/SE/POL/2019 | F8: Pembukuan | H8: WENY ENJELIKA DOLOKSARIBU | I8: VP - Supereditor u068843 | J8: Tidak | K8: Tidak | L8: Simpan
A9: 8 | B9: lorem lorem lorem | E9: 063/SE/POL/2018 | H9: WENY ENJELIKA DOLOKSARIBU | I9: VP - Supereditor u068843 | J9: Tidak | K9: Tidak | L9: Simpan
A10: 9 | B10: lorem lorem lorem | C10: \\10.5.180.227\Source\bca.jpg | D10: https://vidio.com | E10: 063/SE/POL/2018;063/SE/POL/2019 | F10: Pembukuan;Customer Relationship | H10: FARINA ADZANI ADHISTIRA | I10: Artikel - Supereditor U543390 | J10: Tidak | K10: Tidak | L10: Simpan dan Kirim
A11: 10 | B11: lorem lorem lorem | C11: \\10.5.180.227\Source\bca.jpg | D11: https://vidio.com | E11: 063/SE/POL/2018;063/SE/POL/2019 | F11: Pembukuan;Customer Relationship | H11: FARINA ADZANI ADHISTIRA | I11: Artikel - Supereditor U543390 | J11: Tidak | K11: Tidak | L11: Simpan dan Kirim
A12: 11 | B12: lorem lorem lorem | C12: \\10.5.180.227\Source\bca.jpg | D12: https://vidio.com | E12: 063/SE/POL/2018;063/SE/POL/2019 | F12: Pembukuan | H12: FARINA ADZANI ADHISTIRA | I12: VP - Supereditor U543390 | J12: Tidak | K12: Tidak | L12: Simpan dan Kirim
A13: 12 | B13: lorem lorem lorem | E13: 063/SE/POL/2018 | H13: FARINA ADZANI ADHISTIRA | I13: VP - Supereditor U543390 | J13: Tidak | K13: Tidak | L13: Simpan dan Kirim
A14: 13 | B14: lorem lorem lorem | C14: \\10.5.180.227\Source\bca.jpg | D14: https://vidio.com | E14: 063/SE/POL/2018;063/SE/POL/2019 | F14: Pembukuan;Customer Relationship | H14: FARINA ADZANI ADHISTIRA | I14: Artikel - Supereditor U543390 | J14: Tidak | K14: Tidak | L14: Simpan
A15: 14 | B15: lorem lorem lorem | C15: \\10.5.180.227\Source\bca.jpg | D15: https://vidio.com | E15: 063/SE/POL/2018;063/SE/POL/2019 | F15: Pembukuan;Customer Relationship | H15: FARINA ADZANI ADHISTIRA | I15: Artikel - Supereditor U543390 | J15: Tidak | K15: Tidak | L15: Simpan
A16: 15 | B16: lorem lorem lorem | C16: \\10.5.180.227\Source\bca.jpg | D16: https://vidio.com | E16: 063/SE/POL/2018;063/SE/POL/2019 | F16: Pembukuan | H16: FARINA ADZANI ADHISTIRA | I16: VP - Supereditor U543390 | J16: Tidak | K16: Tidak | L16: Simpan
A17: 16 | B17: lorem lorem lorem | E17: 063/SE/POL/2018 | H17: FARINA ADZANI ADHISTIRA | I17: VP - Supereditor U543390 | J17: Tidak | K17: Tidak | L17: Simpan

Sheet Data Edit Isi Artikel VP
A1: NO | B1: NAMA ARTIKEL/ACCORDION EDIT | C1: EDIT JUDUL ARTIKEL | D1: DESKRIPSI SINGKAT | E1: PATH FILE GAMBAR | F1: URL VIDEO | G1: SK/SE REFERENSI | H1: INFORMASI TERKAIT | I1: SUGGESTION | J1: SIMPAN DAN KIRIM | K1: CATATAN SIMPAN & KIRIM | L1: Preview (Ya/Tidak) | M1: Riwayat Versi (Ya/Tidak) | N1: Pilih (AutoSave/Simpan/Simpan dan Kirim/Batal Simpan/Batal Simpan dan Kirim) | O1: Pilih II (AutoSave/Simpan/Simpan dan Kirim/Batal Simpan/Batal Simpan dan Kirim) | P1: Pilih III (AutoSave/Simpan/Simpan dan Kirim/Batal Simpan/Batal Simpan dan Kirim)
A2: 5 | B2: Tambah Ubah Approved Super Editor Artikel E | C2: Ubah Tambah Ubah Approved Super Editor Artikel E | D2: lorem lorem lorem | E2: \\10.5.180.227\Source\bca.jpg | F2: https://vidio.com | G2: 063/SE/POL/2018;063/SE/POL/2019 | H2: Pembukuan;Customer Relationship | J2: WENY ENJELIKA DOLOKSARIBU | K2: Artikel - Supereditor u068843 | L2: Tidak | M2: Tidak | N2: Simpan dan Kirim
A3: 6 | B3: Tambah Ubah Reject Super Editor Artikel F | C3: Ubah Tambah Ubah Reject Super Editor Artikel F | D3: lorem lorem lorem | E3: \\10.5.180.227\Source\bca.jpg | F3: https://vidio.com | G3: 063/SE/POL/2018;063/SE/POL/2019 | H3: Pembukuan;Customer Relationship | J3: WENY ENJELIKA DOLOKSARIBU | K3: Artikel - Supereditor u068843 | L3: Tidak | M3: Tidak | N3: Simpan dan Kirim
A4: 7 | B4: Tambah Ubah Approved Super Editor VP G | C4: Ubah Tambah Ubah Approved Super Editor VP G | D4: lorem lorem lorem | E4: \\10.5.180.227\Source\bca.jpg | F4: https://vidio.com | G4: 063/SE/POL/2018;063/SE/POL/2019 | H4: Pembukuan | J4: WENY ENJELIKA DOLOKSARIBU | K4: VP - Supereditor u068843 | L4: Tidak | M4: Tidak | N4: Simpan dan Kirim
A5: 8 | B5: Tambah Ubah Reject Super Editor VP H | C5: Ubah Tambah Ubah Reject Super Editor VP H | D5: lorem lorem lorem | E5: \\10.5.180.227\Source\bca.jpg | F5: https://vidio.com | G5: 063/SE/POL/2018 | H5: Customer Relationship | J5: WENY ENJELIKA DOLOKSARIBU | K5: VP - Supereditor u068843 | L5: Tidak | M5: Tidak | N5: Simpan dan Kirim
A6: 13 | B6: Tambah Ubah Approved Publisher Artikel M | C6: Ubah Tambah Ubah Approved Publisher Artikel M | D6: lorem lorem lorem | E6: \\10.5.180.227\Source\bca.jpg | F6: https://vidio.com | G6: 063/SE/POL/2018;063/SE/POL/2019 | H6: Pembukuan;Customer Relationship | J6: FARINA ADZANI ADHISTIRA | K6: Artikel - Supereditor U543390 | L6: Tidak | M6: Tidak | N6: Simpan dan Kirim
A7: 14 | B7: Tambah Ubah Reject Publisher Artikel N | C7: Ubah Tambah Ubah Reject Publisher Artikel N | D7: lorem lorem lorem | E7: \\10.5.180.227\Source\bca.jpg | F7: https://vidio.com | G7: 063/SE/POL/2018;063/SE/POL/2019 | H7: Pembukuan;Customer Relationship | J7: FARINA ADZANI ADHISTIRA | K7: Artikel - Supereditor U543390 | L7: Tidak | M7: Tidak | N7: Simpan dan Kirim
A8: 15 | B8: Tambah Ubah Approved Publisher VP O | C8: Ubah Tambah Ubah Approved Publisher VP O | D8: lorem lorem lorem | E8: \\10.5.180.227\Source\bca.jpg | F8: https://vidio.com | G8: 063/SE/POL/2018;063/SE/POL/2019 | H8: Pembukuan | J8: FARINA ADZANI ADHISTIRA | K8: VP - Supereditor U543390 | L8: Tidak | M8: Tidak | N8: Simpan dan Kirim
A9: 16 | B9: Tambah Ubah Reject Publisher VP P | C9: Ubah Tambah Ubah Reject Publisher VP P | D9: lorem lorem lorem | E9: \\10.5.180.227\Source\bca.jpg | F9: https://vidio.com | G9: 063/SE/POL/2018 | H9: Customer Relationship | J9: FARINA ADZANI ADHISTIRA | K9: VP - Supereditor U543390 | L9: Tidak | M9: Tidak | N9: Simpan dan Kirim

Sheet Data Tambah Topik Artikel VP
A1: NO | B1: JUDUL PARENT TOPIK | C1: JUDUL TOPIK | D1: ISI TOPIK | E1: Simpan (Ya/Tidak)
A2: 1 | C2: Ketentuan Tambah Approved Super Editor Artikel A | D2: Isi Ketentuan artikel Super Editor | E2: Ya
A3: 1 | C3: Formulir Tambah Approved Super Editor Artikel A | D3: Isi Formulir artikel Super Editor | E3: Ya
A4: 2 | C4: Ketentuan Tambah Reject Super Editor Artikel B | D4: Isi Ketentuan artikel Super Editor | E4: Ya
A5: 2 | C5: Formulir Tambah Reject Super Editor Artikel B | D5: Isi Formulir artikel Super Editor | E5: Ya
A6: 3 | C6: Ketentuan Tambah Approved Super Editor VP C | D6: Isi Ketentuan artikel Super Editor | E6: Ya
A7: 3 | C7: Formulir Tambah Approved Super Editor VP C | D7: Isi Formulir artikel Super Editor | E7: Ya
A8: 4 | C8: Ketentuan Tambah Reject Super Editor VP D | D8: Isi Ketentuan artikel Super Editor | E8: Ya
A9: 4 | C9: Formulir Tambah Reject Super Editor VP D | D9: Isi Formulir artikel Super Editor | E9: Ya
A10: 5 | C10: Ketentuan Tambah Ubah Approved Super Editor Artikel E | D10: Isi Ketentuan artikel Super Editor | E10: Ya
A11: 5 | C11: Formulir Tambah Ubah Approved Super Editor Artikel E | D11: Isi Formulir artikel Super Editor | E11: Ya
A12: 6 | C12: Ketentuan Tambah Ubah Reject Super Editor Artikel F | D12: Isi Ketentuan artikel Super Editor | E12: Ya
A13: 6 | C13: Formulir Tambah Ubah Reject Super Editor Artikel F | D13: Isi Formulir artikel Super Editor | E13: Ya
... A33: 16 | C33: Formulir Tambah Ubah Reject Publisher VP P | D33: Isi Formulir artikel Publisher | E33: Ya

Sheet Data Artikel VP
A1: NO | B1: JUDUL ARTIKEL | C1: DESKRIPSI SINGKAT | D1: PATH FILE GAMBAR | E1: URL VIDEO | F1: SK/SE REFERENSI | G1: INFORMASI TERKAIT | H1: SUGGESTION | I1: SIMPAN DAN KIRIM | J1: CATATAN SIMPAN & KIRIM | K1: DURASI WAIT | L1: ACTION AFTER 1 | M1: ACTION AFTER 2 | N1: ACTION AFTER 3 | O1: ACTION AFTER 4 | P1: ACTION AFTER 5
A2: 1 | L2: Simpan
A3: 2 | L3: Simpan
A4: 3 | L4: Simpan
A5: 4 | B5: Coba tambah artikel Publisher 1 ubah | C5: lorem lorem Hyperlink Ubah | E5: https://vidio-ubah.com | F5: 063/SE/POL/2018 | G5: Customer Relationship | H5: Penanganan Pengaduan Nasabah;Pengenalan Nasabah | I5: RADITIA FEBIYANTO | J5: Artikel - Editor u060242 | L5: Simpan
A6: 5 | I6: RADITIA FEBIYANTO | J6: Artikel - Editor u060242 | L6: Simpan
A7: 6 | C7: lorem | D7: \\10.5.180.227\Source\bca.jpg | E7: https://vidio.com | F7: 063/SE/POL/2018;063/SE/POL/2019 | G7: Pembukuan;Customer Relationship | I7: RADITIA FEBIYANTO | J7: Artikel - Editor u060242 | L7: Simpan
A8: 7 | C8: lorem | D8: \\10.5.180.227\Source\bca.jpg | E8: https://vidio.com | F8: 063/SE/POL/2018;063/SE/POL/2019 | G8: Pembukuan;Customer Relationship | I8: RADITIA FEBIYANTO | J8: Artikel - Editor u060242 | L8: Simpan
A9: 8 | C9: lorem | D9: \\10.5.180.227\Source\bca.jpg | E9: https://vidio.com | F9: 063/SE/POL/2018;063/SE/POL/2019 | G9: Pembukuan;Customer Relationship | I9: SAMUEL MARANOW | J9: Artikel - Editor u060242 | L9: Simpan
A10: 9 | I10: RADITIA FEBIYANTO | J10: Artikel - Editor u060242 | L10: Simpan
A11: 10 | L11: Simpan
A12: 11 | L12: Simpan
A13: 12 | L13: Simpan
A14: 13 | L14: Simpan
A15: 14 | L15: Simpan
A16: 15 | L16: Simpan
A17: 16 | L17: Simpan
A18: 17 | L18: Simpan
A19: 18 | L19: Simpan
A20: 19 | L20: Simpan
A21: 20 | L21: Simpan
A22: 21 | L22: Simpan
A23: 25 | K23: 10 | L23: Keluar

Sheet Data Hapus Accordion
A1: NO | B1: JUDUL TOPIK | C1: Hapus Accordion (Yes/No)

Sheet Tambah Approve Super Editor
A1: Testcase | B1: Is_Running | C1: Keyword | D1: Pagename | E1: ObjectName | F1: ObjectType | G1: Value | H1: Application
A2: Login A | B2: No | H2: PAKAR
C3: set_specific_wp | G3: Login Super Editor
C4: start_chrome_driver
C5: go_to_url | G5: =Datatable!$R$1 -> URL PAKAR
C6: wait_until_web_element_exist | E6: fieldUserID_pakar
C7: screenshot
C8: set_text | E8: fieldUserID_pakar | G8: =Datatable!$J$1 -> USER ID SUPER EDITOR A
C9: set_text | E9: fieldUserPassword_pakar | G9: =Datatable!$K$1 -> PASSWORD SUPER EDITOR A
C10: screenshot
C11: click | E11: btnSubmitLogin_pakar
C12: debug
A13: Tambah Artikel | B13: No | H13: PAKAR
C14: debug
C15: if_exist_go_to_value | E15: btnPelajariNanti_pakar | G15: PELAJARI NANTI
C16: anchor_go_to_value | G16: PELAJARI NANTI
C17: wait_until_web_element_exist | E17: btnPelajariNanti_pakar
C18: screenshot
C19: click | E19: btnPelajariNanti_pakar
C20: anchor_go_to_value | G20: END_IF_EXIST
C21: wait_for_seconds | G21: 2
C22: screenshot
C23: for_data_by_sheet | G23: Data Tambah Artikel VP;End Data Tambah Artikel VP
C24: click | E24: btnTambahHalaman_pakar
C25: go_to_value | G25: ='Data Tambah Artikel VP'!$B$1 -> PILIH (Artikel/Virtual Page)
C26: anchor_go_to_value | G26: Artikel
C27: wait_until_web_element_exist | E27: btnArtikelTbhHlm_pakar
C28: screenshot
C29: click | E29: btnArtikelTbhHlm_pakar
C30: set_text | E30: fieldNamaArtikel_pakar | G30: ='Data Tambah Artikel VP'!$C$1 -> NAMA ARTIKEL VP
C31: click | E31: btnLokasiArtikel_pakar
C32: wait_for_seconds | G32: 2
C33: click_lokasi | E33: btnLokasiArtikelLv1_pakar | G33: ='Data Tambah Artikel VP'!$E$1 -> LOKASI ARTIKEL VP
C34: click_replace | E34: rbtnTemplate_pakar | G34: ='Data Tambah Artikel VP'!$F$1 -> REKOMENDASI TEMPLATE
C35: wait_until_web_element_exist | E35: btnTambahArtikel_pakar
C36: screenshot
C37: click | E37: btnTambahArtikel_pakar
C38: go_to_value | G38: End Tambah
C39: anchor_go_to_value | G39: Virtual Page
C40: wait_until_web_element_exist | E40: btnVirtualPageHome_pakar
...

Sheet Tambah Reject Super Editor
A1: Testcase | B1: Is_Running | C1: Keyword | D1: Pagename | E1: ObjectName | F1: ObjectType | G1: Value | H1: Application
A2: Login A | B2: Yes | H2: PAKAR
C3: set_specific_wp | G3: Login Super Editor
C4: start_chrome_driver
C5: go_to_url | G5: =Datatable!$R$1 -> URL PAKAR
C6: wait_until_web_element_exist | E6: fieldUserID_pakar
C7: screenshot
C8: set_text | E8: fieldUserID_pakar | G8: =Datatable!$J$1 -> USER ID SUPER EDITOR A
C9: set_text | E9: fieldUserPassword_pakar | G9: =Datatable!$K$1 -> PASSWORD SUPER EDITOR A
C10: screenshot
C11: click | E11: btnSubmitLogin_pakar
C12: debug
A13: Tambah Artikel | B13: Yes | H13: PAKAR
C14: debug
C15: if_exist_go_to_value | E15: btnPelajariNanti_pakar | G15: PELAJARI NANTI
C16: anchor_go_to_value | G16: PELAJARI NANTI
C17: wait_until_web_element_exist | E17: btnPelajariNanti_pakar
C18: screenshot
C19: click | E19: btnPelajariNanti_pakar
C20: anchor_go_to_value | G20: END_IF_EXIST
C21: wait_for_seconds | G21: 2
C22: screenshot
C23: for_data_by_sheet | G23: Data Tambah Artikel VP;End Data Tambah Artikel VP
C24: click | E24: btnTambahHalaman_pakar
C25: go_to_value | G25: ='Data Tambah Artikel VP'!$B$1 -> PILIH (Artikel/Virtual Page)
C26: anchor_go_to_value | G26: Artikel
C27: wait_until_web_element_exist | E27: btnArtikelTbhHlm_pakar
C28: screenshot
C29: click | E29: btnArtikelTbhHlm_pakar
C30: set_text | E30: fieldNamaArtikel_pakar | G30: ='Data Tambah Artikel VP'!$C$1 -> NAMA ARTIKEL VP
C31: click | E31: btnLokasiArtikel_pakar
C32: wait_for_seconds | G32: 2
C33: click_lokasi | E33: btnLokasiArtikelLv1_pakar | G33: ='Data Tambah Artikel VP'!$E$1 -> LOKASI ARTIKEL VP
C34: click_replace | E34: rbtnTemplate_pakar | G34: ='Data Tambah Artikel VP'!$F$1 -> REKOMENDASI TEMPLATE
C35: wait_until_web_element_exist | E35: btnTambahArtikel_pakar
C36: screenshot
C37: click | E37: btnTambahArtikel_pakar
C38: go_to_value | G38: End Tambah
C39: anchor_go_to_value | G39: Virtual Page
C40: wait_until_web_element_exist | E40: btnVirtualPageHome_pakar
...

Sheet Tambah Approve Publisher
A1: Testcase | B1: Is_Running | C1: Keyword | D1: Pagename | E1: ObjectName | F1: ObjectType | G1: Value | H1: Application
A2: Login A | B2: Yes | H2: PAKAR
C3: set_specific_wp | G3: Login Super Editor
C4: start_chrome_driver
C5: go_to_url | G5: =Datatable!$R$1 -> URL PAKAR
C6: wait_until_web_element_exist | E6: fieldUserID_pakar
C7: screenshot
C8: set_text | E8: fieldUserID_pakar | G8: =Datatable!$J$1 -> USER ID SUPER EDITOR A
C9: set_text | E9: fieldUserPassword_pakar | G9: =Datatable!$K$1 -> PASSWORD SUPER EDITOR A
C10: screenshot
C11: click | E11: btnSubmitLogin_pakar
C12: debug
A13: Tambah Artikel | B13: Yes | H13: PAKAR
C14: debug
C15: if_exist_go_to_value | E15: btnPelajariNanti_pakar | G15: PELAJARI NANTI
C16: anchor_go_to_value | G16: PELAJARI NANTI
C17: wait_until_web_element_exist | E17: btnPelajariNanti_pakar
C18: screenshot
C19: click | E19: btnPelajariNanti_pakar
C20: anchor_go_to_value | G20: END_IF_EXIST
C21: wait_for_seconds | G21: 2
C22: screenshot
C23: for_data_by_sheet | G23: Data Tambah Artikel VP;End Data Tambah Artikel VP
C24: click | E24: btnTambahHalaman_pakar
C25: go_to_value | G25: ='Data Tambah Artikel VP'!$B$1 -> PILIH (Artikel/Virtual Page)
C26: anchor_go_to_value | G26: Artikel
C27: wait_until_web_element_exist | E27: btnArtikelTbhHlm_pakar
C28: screenshot
C29: click | E29: btnArtikelTbhHlm_pakar
C30: set_text | E30: fieldNamaArtikel_pakar | G30: ='Data Tambah Artikel VP'!$C$1 -> NAMA ARTIKEL VP
C31: click | E31: btnLokasiArtikel_pakar
C32: wait_for_seconds | G32: 2
C33: click_lokasi | E33: btnLokasiArtikelLv1_pakar | G33: ='Data Tambah Artikel VP'!$E$1 -> LOKASI ARTIKEL VP
C34: click_replace | E34: rbtnTemplate_pakar | G34: ='Data Tambah Artikel VP'!$F$1 -> REKOMENDASI TEMPLATE
C35: wait_until_web_element_exist | E35: btnTambahArtikel_pakar
C36: screenshot
C37: click | E37: btnTambahArtikel_pakar
C38: go_to_value | G38: End Tambah
C39: anchor_go_to_value | G39: Virtual Page
C40: wait_until_web_element_exist | E40: btnVirtualPageHome_pakar
...

Sheet Tambah Reject Publisher
A1: Testcase | B1: Is_Running | C1: Keyword | D1: Pagename | E1: ObjectName | F1: ObjectType | G1: Value | H1: Application
A2: Login A | B2: Yes | H2: PAKAR
C3: set_specific_wp | G3: Login Super Editor
C4: start_chrome_driver
C5: go_to_url | G5: =Datatable!$R$1 -> URL PAKAR
C6: wait_until_web_element_exist | E6: fieldUserID_pakar
C7: screenshot
C8: set_text | E8: fieldUserID_pakar | G8: =Datatable!$J$1 -> USER ID SUPER EDITOR A
C9: set_text | E9: fieldUserPassword_pakar | G9: =Datatable!$K$1 -> PASSWORD SUPER EDITOR A
C10: screenshot
C11: click | E11: btnSubmitLogin_pakar
C12: debug
A13: Tambah Artikel | B13: Yes | H13: PAKAR
C14: debug
C15: if_exist_go_to_value | E15: btnPelajariNanti_pakar | G15: PELAJARI NANTI
C16: anchor_go_to_value | G16: PELAJARI NANTI
C17: wait_until_web_element_exist | E17: btnPelajariNanti_pakar
C18: screenshot
C19: click | E19: btnPelajariNanti_pakar
C20: anchor_go_to_value | G20: END_IF_EXIST
C21: wait_for_seconds | G21: 2
C22: screenshot
C23: for_data_by_sheet | G23: Data Tambah Artikel VP;End Data Tambah Artikel VP
C24: click | E24: btnTambahHalaman_pakar
C25: go_to_value | G25: ='Data Tambah Artikel VP'!$B$1 -> PILIH (Artikel/Virtual Page)
C26: anchor_go_to_value | G26: Artikel
C27: wait_until_web_element_exist | E27: btnArtikelTbhHlm_pakar
C28: screenshot
C29: click | E29: btnArtikelTbhHlm_pakar
C30: set_text | E30: fieldNamaArtikel_pakar | G30: ='Data Tambah Artikel VP'!$C$1 -> NAMA ARTIKEL VP
C31: click | E31: btnLokasiArtikel_pakar
C32: wait_for_seconds | G32: 2
C33: click_lokasi | E33: btnLokasiArtikelLv1_pakar | G33: ='Data Tambah Artikel VP'!$E$1 -> LOKASI ARTIKEL VP
C34: click_replace | E34: rbtnTemplate_pakar | G34: ='Data Tambah Artikel VP'!$F$1 -> REKOMENDASI TEMPLATE
C35: wait_until_web_element_exist | E35: btnTambahArtikel_pakar
C36: screenshot
C37: click | E37: btnTambahArtikel_pakar
C38: go_to_value | G38: End Tambah
C39: anchor_go_to_value | G39: Virtual Page
C40: wait_until_web_element_exist | E40: btnVirtualPageHome_pakar
...

Sheet Tambah Ubah Approve SuperEditor
A1: Testcase | B1: Is_Running | C1: Keyword | D1: Pagename | E1: ObjectName | F1: ObjectType | G1: Value | H1: Application
A2: Login A | B2: Yes | H2: PAKAR
C3: set_specific_wp | G3: Login Super Editor
C4: start_chrome_driver
C5: go_to_url | G5: =Datatable!$R$1 -> URL PAKAR
C6: wait_until_web_element_exist | E6: fieldUserID_pakar
C7: screenshot
C8: set_text | E8: fieldUserID_pakar | G8: =Datatable!$J$1 -> USER ID SUPER EDITOR A
C9: set_text | E9: fieldUserPassword_pakar | G9: =Datatable!$K$1 -> PASSWORD SUPER EDITOR A
C10: screenshot
C11: click | E11: btnSubmitLogin_pakar
C12: debug
A13: Tambah Artikel | B13: Yes | H13: PAKAR
C14: debug
C15: if_exist_go_to_value | E15: btnPelajariNanti_pakar | G15: PELAJARI NANTI
C16: anchor_go_to_value | G16: PELAJARI NANTI
C17: wait_until_web_element_exist | E17: btnPelajariNanti_pakar
C18: screenshot
C19: click | E19: btnPelajariNanti_pakar
C20: anchor_go_to_value | G20: END_IF_EXIST
C21: wait_for_seconds | G21: 2
C22: screenshot
C23: for_data_by_sheet | G23: Data Tambah Artikel VP;End Data Tambah Artikel VP
C24: click | E24: btnTambahHalaman_pakar
C25: go_to_value | G25: ='Data Tambah Artikel VP'!$B$1 -> PILIH (Artikel/Virtual Page)
C26: anchor_go_to_value | G26: Artikel
C27: wait_until_web_element_exist | E27: btnArtikelTbhHlm_pakar
C28: screenshot
C29: click | E29: btnArtikelTbhHlm_pakar
C30: set_text | E30: fieldNamaArtikel_pakar | G30: ='Data Tambah Artikel VP'!$C$1 -> NAMA ARTIKEL VP
C31: click | E31: btnLokasiArtikel_pakar
C32: wait_for_seconds | G32: 2
C33: click_lokasi | E33: btnLokasiArtikelLv1_pakar | G33: ='Data Tambah Artikel VP'!$E$1 -> LOKASI ARTIKEL VP
C34: click_replace | E34: rbtnTemplate_pakar | G34: ='Data Tambah Artikel VP'!$F$1 -> REKOMENDASI TEMPLATE
C35: wait_until_web_element_exist | E35: btnTambahArtikel_pakar
C36: screenshot
C37: click | E37: btnTambahArtikel_pakar
C38: go_to_value | G38: End Tambah
C39: anchor_go_to_value | G39: Virtual Page
C40: wait_until_web_element_exist | E40: btnVirtualPageHome_pakar
...

Sheet Tambah Ubah Reject Super Editor
A1: Testcase | B1: Is_Running | C1: Keyword | D1: Pagename | E1: ObjectName | F1: ObjectType | G1: Value | H1: Application
A2: Login A | B2: Yes | H2: PAKAR
C3: set_specific_wp | G3: Login Super Editor
C4: start_chrome_driver
C5: go_to_url | G5: =Datatable!$R$1 -> URL PAKAR
C6: wait_until_web_element_exist | E6: fieldUserID_pakar
C7: screenshot
C8: set_text | E8: fieldUserID_pakar | G8: =Datatable!$J$1 -> USER ID SUPER EDITOR A
C9: set_text | E9: fieldUserPassword_pakar | G9: =Datatable!$K$1 -> PASSWORD SUPER EDITOR A
C10: screenshot
C11: click | E11: btnSubmitLogin_pakar
C12: debug
A13: Tambah Artikel | B13: Yes | H13: PAKAR
C14: debug
C15: if_exist_go_to_value | E15: btnPelajariNanti_pakar | G15: PELAJARI NANTI
C16: anchor_go_to_value | G16: PELAJARI NANTI
C17: wait_until_web_element_exist | E17: btnPelajariNanti_pakar
C18: screenshot
C19: click | E19: btnPelajariNanti_pakar
C20: anchor_go_to_value | G20: END_IF_EXIST
C21: wait_for_seconds | G21: 2
C22: screenshot
C23: for_data_by_sheet | G23: Data Tambah Artikel VP;End Data Tambah Artikel VP
C24: click | E24: btnTambahHalaman_pakar
C25: go_to_value | G25: ='Data Tambah Artikel VP'!$B$1 -> PILIH (Artikel/Virtual Page)
C26: anchor_go_to_value | G26: Artikel
C27: wait_until_web_element_exist | E27: btnArtikelTbhHlm_pakar
C28: screenshot
C29: click | E29: btnArtikelTbhHlm_pakar
C30: set_text | E30: fieldNamaArtikel_pakar | G30: ='Data Tambah Artikel VP'!$C$1 -> NAMA ARTIKEL VP
C31: click | E31: btnLokasiArtikel_pakar
C32: wait_for_seconds | G32: 2
C33: click_lokasi | E33: btnLokasiArtikelLv1_pakar | G33: ='Data Tambah Artikel VP'!$E$1 -> LOKASI ARTIKEL VP
C34: click_replace | E34: rbtnTemplate_pakar | G34: ='Data Tambah Artikel VP'!$F$1 -> REKOMENDASI TEMPLATE
C35: wait_until_web_element_exist | E35: btnTambahArtikel_pakar
C36: screenshot
C37: click | E37: btnTambahArtikel_pakar
C38: go_to_value | G38: End Tambah
C39: anchor_go_to_value | G39: Virtual Page
C40: wait_until_web_element_exist | E40: btnVirtualPageHome_pakar
...

Sheet Tambah Ubah Approve Publisher
A1: Testcase | B1: Is_Running | C1: Keyword | D1: Pagename | E1: ObjectName | F1: ObjectType | G1: Value | H1: Application
A2: Login A | B2: Yes | H2: PAKAR
C3: set_specific_wp | G3: Login Super Editor
C4: start_chrome_driver
C5: go_to_url | G5: =Datatable!$R$1 -> URL PAKAR
C6: wait_until_web_element_exist | E6: fieldUserID_pakar
C7: screenshot
C8: set_text | E8: fieldUserID_pakar | G8: =Datatable!$J$1 -> USER ID SUPER EDITOR A
C9: set_text | E9: fieldUserPassword_pakar | G9: =Datatable!$K$1 -> PASSWORD SUPER EDITOR A
C10: screenshot
C11: click | E11: btnSubmitLogin_pakar
C12: debug
A13: Tambah Artikel | B13: Yes | H13: PAKAR
C14: debug
C15: if_exist_go_to_value | E15: btnPelajariNanti_pakar | G15: PELAJARI NANTI
C16: anchor_go_to_value | G16: PELAJARI NANTI
C17: wait_until_web_element_exist | E17: btnPelajariNanti_pakar
C18: screenshot
C19: click | E19: btnPelajariNanti_pakar
C20: anchor_go_to_value | G20: END_IF_EXIST
C21: wait_for_seconds | G21: 2
C22: screenshot
C23: for_data_by_sheet | G23: Data Tambah Artikel VP;End Data Tambah Artikel VP
C24: click | E24: btnTambahHalaman_pakar
C25: go_to_value | G25: ='Data Tambah Artikel VP'!$B$1 -> PILIH (Artikel/Virtual Page)
C26: anchor_go_to_value | G26: Artikel
C27: wait_until_web_element_exist | E27: btnArtikelTbhHlm_pakar
C28: screenshot
C29: click | E29: btnArtikelTbhHlm_pakar
C30: set_text | E30: fieldNamaArtikel_pakar | G30: ='Data Tambah Artikel VP'!$C$1 -> NAMA ARTIKEL VP
C31: click | E31: btnLokasiArtikel_pakar
C32: wait_for_seconds | G32: 2
C33: click_lokasi | E33: btnLokasiArtikelLv1_pakar | G33: ='Data Tambah Artikel VP'!$E$1 -> LOKASI ARTIKEL VP
C34: click_replace | E34: rbtnTemplate_pakar | G34: ='Data Tambah Artikel VP'!$F$1 -> REKOMENDASI TEMPLATE
C35: wait_until_web_element_exist | E35: btnTambahArtikel_pakar
C36: screenshot
C37: click | E37: btnTambahArtikel_pakar
C38: go_to_value | G38: End Tambah
C39: anchor_go_to_value | G39: Virtual Page
C40: wait_until_web_element_exist | E40: btnVirtualPageHome_pakar
...

Sheet Tambah Ubah Reject Publisher
A1: Testcase | B1: Is_Running | C1: Keyword | D1: Pagename | E1: ObjectName | F1: ObjectType | G1: Value | H1: Application
A2: Login A | B2: Yes | H2: PAKAR
C3: set_specific_wp | G3: Login Super Editor
C4: start_chrome_driver
C5: go_to_url | G5: =Datatable!$R$1 -> URL PAKAR
C6: wait_until_web_element_exist | E6: fieldUserID_pakar
C7: screenshot
C8: set_text | E8: fieldUserID_pakar | G8: =Datatable!$J$1 -> USER ID SUPER EDITOR A
C9: set_text | E9: fieldUserPassword_pakar | G9: =Datatable!$K$1 -> PASSWORD SUPER EDITOR A
C10: screenshot
C11: click | E11: btnSubmitLogin_pakar
C12: debug
A13: Tambah Artikel | B13: Yes | H13: PAKAR
C14: debug
C15: if_exist_go_to_value | E15: btnPelajariNanti_pakar | G15: PELAJARI NANTI
C16: anchor_go_to_value | G16: PELAJARI NANTI
C17: wait_until_web_element_exist | E17: btnPelajariNanti_pakar
C18: screenshot
C19: click | E19: btnPelajariNanti_pakar
C20: anchor_go_to_value | G20: END_IF_EXIST
C21: wait_for_seconds | G21: 2
C22: screenshot
C23: for_data_by_sheet | G23: Data Tambah Artikel VP;End Data Tambah Artikel VP
C24: click | E24: btnTambahHalaman_pakar
C25: go_to_value | G25: ='Data Tambah Artikel VP'!$B$1 -> PILIH (Artikel/Virtual Page)
C26: anchor_go_to_value | G26: Artikel
C27: wait_until_web_element_exist | E27: btnArtikelTbhHlm_pakar
C28: screenshot
C29: click | E29: btnArtikelTbhHlm_pakar
C30: set_text | E30: fieldNamaArtikel_pakar | G30: ='Data Tambah Artikel VP'!$C$1 -> NAMA ARTIKEL VP
C31: click | E31: btnLokasiArtikel_pakar
C32: wait_for_seconds | G32: 2
C33: click_lokasi | E33: btnLokasiArtikelLv1_pakar | G33: ='Data Tambah Artikel VP'!$E$1 -> LOKASI ARTIKEL VP
C34: click_replace | E34: rbtnTemplate_pakar | G34: ='Data Tambah Artikel VP'!$F$1 -> REKOMENDASI TEMPLATE
C35: wait_until_web_element_exist | E35: btnTambahArtikel_pakar
C36: screenshot
C37: click | E37: btnTambahArtikel_pakar
C38: go_to_value | G38: End Tambah
C39: anchor_go_to_value | G39: Virtual Page
C40: wait_until_web_element_exist | E40: btnVirtualPageHome_pakar
...

Sheet Ubah Approved Super Editor
A1: Testcase | B1: Is_Running | C1: Keyword | D1: Pagename | E1: ObjectName | F1: ObjectType | G1: Value | H1: Application
A2: Login A | B2: Yes | H2: PAKAR
C3: set_specific_wp | G3: Login Super Editor
C4: start_chrome_driver
C5: go_to_url | G5: =Datatable!$R$1 -> URL PAKAR
C6: wait_until_web_element_exist | E6: fieldUserID_pakar
C7: screenshot
C8: set_text | E8: fieldUserID_pakar | G8: =Datatable!$J$1 -> USER ID SUPER EDITOR A
C9: set_text | E9: fieldUserPassword_pakar | G9: =Datatable!$K$1 -> PASSWORD SUPER EDITOR A
C10: screenshot
C11: click | E11: btnSubmitLogin_pakar
C12: debug
A13: Akses Artikel Main Search | B13: Yes | H13: PAKAR
C14: for_data_by_sheet | G14: Data Akses Artikel;End Data Akses Artikel
C15: wait_for_seconds | G15: 1
C16: set_text | E16: fieldCariDi_pakar | G16: ='Data Akses Artikel'!$J$1 -> NAMA ARTIKEL (Didalam Folder pisahkan ;)
C17: wait_for_seconds | G17: 1
C18: screenshot
C19: hover_to_element | E19: btnSearch_pakar
C20: click | E20: btnSearch_pakar
C21: wait_until_web_element_exist | E21: txtHasilPencarian_pakar
C22: screenshot
C23: hover_and_click_replace | E23: txtSearchJudul_pakar | G23: ='Data Akses Artikel'!$J$1 -> NAMA ARTIKEL (Didalam Folder pisahkan ;)
C24: wait_until_web_element_exist | E24: cardFeedback_pakar
C25: wait_for_seconds | G25: 1
C26: screenshot
C27: end_data_for_sheet | G27: End Data Akses Artikel
A28: Edit Artikel VP | B28: Yes | H28: PAKAR
C29: set_wp | G29: Akses Edit Halaman Artikel VP
C30: for_data_by_sheet | G30: Data Edit Isi Artikel VP;End Data Edit Isi Artikel VP
C31: expand_all_accordion | E31: btnAccordionArtikel_pakar
C32: hover_to_element_replace | E32: btnPensilAllHalArtikel_pakar | G32: ='Data Edit Isi Artikel VP'!$B$1 -> NAMA ARTIKEL/ACCORDION EDIT
C33: click_replace | E33: btnPensilAllHalArtikel_pakar | G33: ='Data Edit Isi Artikel VP'!$B$1 -> NAMA ARTIKEL/ACCORDION EDIT
C34: click_if_exist | E34: btnModalUbah_pakar
C35: wait_until_web_element_exist | E35: btnSimpanDanKirimTopBar_pakar
C36: wait_for_seconds | G36: 1
C37: screenshot
C38: set_wp | G38: Tambah Judul
C39: if_null_go_to_value | G39: ='Data Edit Isi Artikel VP'!$C$1 -> EDIT JUDUL ARTIKEL
C40: anchor_go_to_value | G40: #Not_Null
...

Sheet Ubah Reject Super Editor
A1: Testcase | B1: Is_Running | C1: Keyword | D1: Pagename | E1: ObjectName | F1: ObjectType | G1: Value | H1: Application
A2: Login A | B2: Yes | H2: PAKAR
C3: set_specific_wp | G3: Login Super Editor
C4: start_chrome_driver
C5: go_to_url | G5: =Datatable!$R$1 -> URL PAKAR
C6: wait_until_web_element_exist | E6: fieldUserID_pakar
C7: screenshot
C8: set_text | E8: fieldUserID_pakar | G8: =Datatable!$J$1 -> USER ID SUPER EDITOR A
C9: set_text | E9: fieldUserPassword_pakar | G9: =Datatable!$K$1 -> PASSWORD SUPER EDITOR A
C10: screenshot
C11: click | E11: btnSubmitLogin_pakar
C12: debug
A13: Akses Artikel Main Search | B13: Yes | H13: PAKAR
C14: for_data_by_sheet | G14: Data Akses Artikel;End Data Akses Artikel
C15: wait_for_seconds | G15: 1
C16: set_text | E16: fieldCariDi_pakar | G16: ='Data Akses Artikel'!$J$1 -> NAMA ARTIKEL (Didalam Folder pisahkan ;)
C17: wait_for_seconds | G17: 1
C18: screenshot
C19: hover_to_element | E19: btnSearch_pakar
C20: click | E20: btnSearch_pakar
C21: wait_until_web_element_exist | E21: txtHasilPencarian_pakar
C22: screenshot
C23: hover_and_click_replace | E23: txtSearchJudul_pakar | G23: ='Data Akses Artikel'!$J$1 -> NAMA ARTIKEL (Didalam Folder pisahkan ;)
C24: wait_until_web_element_exist | E24: cardFeedback_pakar
C25: wait_for_seconds | G25: 1
C26: screenshot
C27: end_data_for_sheet | G27: End Data Akses Artikel
A28: Edit Artikel VP | B28: Yes | H28: PAKAR
C29: set_wp | G29: Akses Edit Halaman Artikel VP
C30: for_data_by_sheet | G30: Data Edit Isi Artikel VP;End Data Edit Isi Artikel VP
C31: expand_all_accordion | E31: btnAccordionArtikel_pakar
C32: hover_to_element_replace | E32: btnPensilAllHalArtikel_pakar | G32: ='Data Edit Isi Artikel VP'!$B$1 -> NAMA ARTIKEL/ACCORDION EDIT
C33: click_replace | E33: btnPensilAllHalArtikel_pakar | G33: ='Data Edit Isi Artikel VP'!$B$1 -> NAMA ARTIKEL/ACCORDION EDIT
C34: click_if_exist | E34: btnModalUbah_pakar
C35: wait_until_web_element_exist | E35: btnSimpanDanKirimTopBar_pakar
C36: wait_for_seconds | G36: 1
C37: screenshot
C38: set_wp | G38: Tambah Judul
C39: if_null_go_to_value | G39: ='Data Edit Isi Artikel VP'!$C$1 -> EDIT JUDUL ARTIKEL
C40: anchor_go_to_value | G40: #Not_Null
...

Sheet Ubah Approved Publisher
A1: Testcase | B1: Is_Running | C1: Keyword | D1: Pagename | E1: ObjectName | F1: ObjectType | G1: Value | H1: Application
A2: Login A | B2: Yes | H2: PAKAR
C3: set_specific_wp | G3: Login Super Editor
C4: start_chrome_driver
C5: go_to_url | G5: =Datatable!$R$1 -> URL PAKAR
C6: wait_until_web_element_exist | E6: fieldUserID_pakar
C7: screenshot
C8: set_text | E8: fieldUserID_pakar | G8: =Datatable!$J$1 -> USER ID SUPER EDITOR A
C9: set_text | E9: fieldUserPassword_pakar | G9: =Datatable!$K$1 -> PASSWORD SUPER EDITOR A
C10: screenshot
C11: click | E11: btnSubmitLogin_pakar
C12: debug
A13: Akses Artikel Main Search | B13: Yes | H13: PAKAR
C14: for_data_by_sheet | G14: Data Akses Artikel;End Data Akses Artikel
C15: wait_for_seconds | G15: 1
C16: set_text | E16: fieldCariDi_pakar | G16: ='Data Akses Artikel'!$J$1 -> NAMA ARTIKEL (Didalam Folder pisahkan ;)
C17: wait_for_seconds | G17: 1
C18: screenshot
C19: hover_to_element | E19: btnSearch_pakar
C20: click | E20: btnSearch_pakar
C21: wait_until_web_element_exist | E21: txtHasilPencarian_pakar
C22: screenshot
C23: hover_and_click_replace | E23: txtSearchJudul_pakar | G23: ='Data Akses Artikel'!$J$1 -> NAMA ARTIKEL (Didalam Folder pisahkan ;)
C24: wait_until_web_element_exist | E24: cardFeedback_pakar
C25: wait_for_seconds | G25: 1
C26: screenshot
C27: end_data_for_sheet | G27: End Data Akses Artikel
A28: Edit Artikel VP | B28: Yes | H28: PAKAR
C29: set_wp | G29: Akses Edit Halaman Artikel VP
C30: for_data_by_sheet | G30: Data Edit Isi Artikel VP;End Data Edit Isi Artikel VP
C31: expand_all_accordion | E31: btnAccordionArtikel_pakar
C32: hover_to_element_replace | E32: btnPensilAllHalArtikel_pakar | G32: ='Data Edit Isi Artikel VP'!$B$1 -> NAMA ARTIKEL/ACCORDION EDIT
C33: click_replace | E33: btnPensilAllHalArtikel_pakar | G33: ='Data Edit Isi Artikel VP'!$B$1 -> NAMA ARTIKEL/ACCORDION EDIT
C34: click_if_exist | E34: btnModalUbah_pakar
C35: wait_until_web_element_exist | E35: btnSimpanDanKirimTopBar_pakar
C36: wait_for_seconds | G36: 1
C37: screenshot
C38: set_wp | G38: Tambah Judul
C39: if_null_go_to_value | G39: ='Data Edit Isi Artikel VP'!$C$1 -> EDIT JUDUL ARTIKEL
C40: anchor_go_to_value | G40: #Not_Null
...

Sheet Ubah Reject Publisher
A1: Testcase | B1: Is_Running | C1: Keyword | D1: Pagename | E1: ObjectName | F1: ObjectType | G1: Value | H1: Application
A2: Login A | B2: Yes | H2: PAKAR
C3: set_specific_wp | G3: Login Super Editor
C4: start_chrome_driver
C5: go_to_url | G5: =Datatable!$R$1 -> URL PAKAR
C6: wait_until_web_element_exist | E6: fieldUserID_pakar
C7: screenshot
C8: set_text | E8: fieldUserID_pakar | G8: =Datatable!$J$1 -> USER ID SUPER EDITOR A
C9: set_text | E9: fieldUserPassword_pakar | G9: =Datatable!$K$1 -> PASSWORD SUPER EDITOR A
C10: screenshot
C11: click | E11: btnSubmitLogin_pakar
C12: debug
A13: Akses Artikel Main Search | B13: Yes | H13: PAKAR
C14: for_data_by_sheet | G14: Data Akses Artikel;End Data Akses Artikel
C15: wait_for_seconds | G15: 1
C16: set_text | E16: fieldCariDi_pakar | G16: ='Data Akses Artikel'!$J$1 -> NAMA ARTIKEL (Didalam Folder pisahkan ;)
C17: wait_for_seconds | G17: 1
C18: screenshot
C19: hover_to_element | E19: btnSearch_pakar
C20: click | E20: btnSearch_pakar
C21: wait_until_web_element_exist | E21: txtHasilPencarian_pakar
C22: screenshot
C23: hover_and_click_replace | E23: txtSearchJudul_pakar | G23: ='Data Akses Artikel'!$J$1 -> NAMA ARTIKEL (Didalam Folder pisahkan ;)
C24: wait_until_web_element_exist | E24: cardFeedback_pakar
C25: wait_for_seconds | G25: 1
C26: screenshot
C27: end_data_for_sheet | G27: End Data Akses Artikel
A28: Edit Artikel VP | B28: Yes | H28: PAKAR
C29: set_wp | G29: Akses Edit Halaman Artikel VP
C30: for_data_by_sheet | G30: Data Edit Isi Artikel VP;End Data Edit Isi Artikel VP
C31: expand_all_accordion | E31: btnAccordionArtikel_pakar
C32: hover_to_element_replace | E32: btnPensilAllHalArtikel_pakar | G32: ='Data Edit Isi Artikel VP'!$B$1 -> NAMA ARTIKEL/ACCORDION EDIT
C33: click_replace | E33: btnPensilAllHalArtikel_pakar | G33: ='Data Edit Isi Artikel VP'!$B$1 -> NAMA ARTIKEL/ACCORDION EDIT
C34: click_if_exist | E34: btnModalUbah_pakar
C35: wait_until_web_element_exist | E35: btnSimpanDanKirimTopBar_pakar
C36: wait_for_seconds | G36: 1
C37: screenshot
C38: set_wp | G38: Tambah Judul
C39: if_null_go_to_value | G39: ='Data Edit Isi Artikel VP'!$C$1 -> EDIT JUDUL ARTIKEL
C40: anchor_go_to_value | G40: #Not_Null
...

Sheet Ubah Negatif Approve SuperEdito
A1: Testcase | B1: Is_Running | C1: Keyword | D1: Pagename | E1: ObjectName | F1: ObjectType | G1: Value | H1: Application
A2: Login A | B2: Yes | H2: PAKAR
C3: set_specific_wp | G3: Login Super Editor
C4: start_chrome_driver
C5: go_to_url | G5: =Datatable!$R$1 -> URL PAKAR
C6: wait_until_web_element_exist | E6: fieldUserID_pakar
C7: screenshot
C8: set_text | E8: fieldUserID_pakar | G8: =Datatable!$J$1 -> USER ID SUPER EDITOR A
C9: set_text | E9: fieldUserPassword_pakar | G9: =Datatable!$K$1 -> PASSWORD SUPER EDITOR A
C10: screenshot
C11: click | E11: btnSubmitLogin_pakar
C12: debug
A13: Akses Artikel Main Search | B13: Yes | H13: PAKAR
C14: for_data_by_sheet | G14: Data Akses Artikel;End Data Akses Artikel
C15: wait_for_seconds | G15: 1
C16: set_text | E16: fieldCariDi_pakar | G16: ='Data Akses Artikel'!$J$1 -> NAMA ARTIKEL (Didalam Folder pisahkan ;)
C17: wait_for_seconds | G17: 1
C18: screenshot
C19: hover_to_element | E19: btnSearch_pakar
C20: click | E20: btnSearch_pakar
C21: wait_until_web_element_exist | E21: txtHasilPencarian_pakar
C22: screenshot
C23: hover_and_click_replace | E23: txtSearchJudul_pakar | G23: ='Data Akses Artikel'!$J$1 -> NAMA ARTIKEL (Didalam Folder pisahkan ;)
C24: wait_until_web_element_exist | E24: cardFeedback_pakar
C25: wait_for_seconds | G25: 1
C26: screenshot
C27: end_data_for_sheet | G27: End Data Akses Artikel
A28: Edit Artikel VP | B28: Yes | H28: PAKAR
C29: set_wp | G29: Akses Edit Halaman Artikel VP
C30: for_data_by_sheet | G30: Data Edit Isi Artikel VP;End Data Edit Isi Artikel VP
C31: expand_all_accordion | E31: btnAccordionArtikel_pakar
C32: hover_to_element_replace | E32: btnPensilAllHalArtikel_pakar | G32: ='Data Edit Isi Artikel VP'!$B$1 -> NAMA ARTIKEL/ACCORDION EDIT
C33: click_replace | E33: btnPensilAllHalArtikel_pakar | G33: ='Data Edit Isi Artikel VP'!$B$1 -> NAMA ARTIKEL/ACCORDION EDIT
C34: click_if_exist | E34: btnModalUbah_pakar
C35: wait_until_web_element_exist | E35: btnSimpanDanKirimTopBar_pakar
C36: wait_for_seconds | G36: 1
C37: screenshot
C38: set_wp | G38: Tambah Judul
C39: if_null_go_to_value | G39: ='Data Edit Isi Artikel VP'!$C$1 -> EDIT JUDUL ARTIKEL
C40: anchor_go_to_value | G40: #Not_Null
...

Sheet Ubah Negatif Reject SuperEdito
A1: Testcase | B1: Is_Running | C1: Keyword | D1: Pagename | E1: ObjectName | F1: ObjectType | G1: Value | H1: Application
A2: Login A | B2: Yes | H2: PAKAR
C3: set_specific_wp | G3: Login Super Editor
C4: start_chrome_driver
C5: go_to_url | G5: =Datatable!$R$1 -> URL PAKAR
C6: wait_until_web_element_exist | E6: fieldUserID_pakar
C7: screenshot
C8: set_text | E8: fieldUserID_pakar | G8: =Datatable!$J$1 -> USER ID SUPER EDITOR A
C9: set_text | E9: fieldUserPassword_pakar | G9: =Datatable!$K$1 -> PASSWORD SUPER EDITOR A
C10: screenshot
C11: click | E11: btnSubmitLogin_pakar
C12: debug
A13: Akses Artikel Main Search | B13: Yes | H13: PAKAR
C14: for_data_by_sheet | G14: Data Akses Artikel;End Data Akses Artikel
C15: wait_for_seconds | G15: 1
C16: set_text | E16: fieldCariDi_pakar | G16: ='Data Akses Artikel'!$J$1 -> NAMA ARTIKEL (Didalam Folder pisahkan ;)
C17: wait_for_seconds | G17: 1
C18: screenshot
C19: hover_to_element | E19: btnSearch_pakar
C20: click | E20: btnSearch_pakar
C21: wait_until_web_element_exist | E21: txtHasilPencarian_pakar
C22: screenshot
C23: hover_and_click_replace | E23: txtSearchJudul_pakar | G23: ='Data Akses Artikel'!$J$1 -> NAMA ARTIKEL (Didalam Folder pisahkan ;)
C24: wait_until_web_element_exist | E24: cardFeedback_pakar
C25: wait_for_seconds | G25: 1
C26: screenshot
C27: end_data_for_sheet | G27: End Data Akses Artikel
A28: Edit Artikel VP | B28: Yes | H28: PAKAR
C29: set_wp | G29: Akses Edit Halaman Artikel VP
C30: for_data_by_sheet | G30: Data Edit Isi Artikel VP;End Data Edit Isi Artikel VP
